Workbook

Sheet ReadMe
A1: Title | B1: Deep Proteomic Profiling of
B2: Vasopressin-Sensitive Collecting Duct Cells
B3: II. Bioinformatic Analysis of Vasopressin Signaling
A5: Authors | B5: Chin-Rang Yang, Viswanathan Raghuram, Milad Emamian,
B6: Pablo C. Sandoval and Mark A. Knepper‡
A8: Affiliation | B8: Epithelial Systems Biology Laboratory
B9: NHLBI, National Institutes of Health,
B10: Bethesda, MD 20892‐1603, USA
A17: Contents: | B17: Summary : Ranking of kinases that could phosphorylate Aqp2 @ S261 and their Bayes' Probability
B18: Micro Array: Application of Bayes Rule on mpkCCD Micro Array
B19: Proteome: Application of Bayes rule on mpkCCD protoeme using the prior probabilities calculated from Micro Array
B20: Consensus Phospho Site: Application of Bayes rule on mpkCCD protoeme using the prior probabilities obtained from Proteome
B21: AVP Regulation: Application of Bayes rule on Kinases known to be PTM by AVP, using the prior probabilities calculated from consensus phopho site & Ca2+&cAMP: Application of Bayes rule on kinases known to actvated by Ca2+ or cAMP, prior probabilities calculated from previous analysis
B22: Aqp2 colocalization; Application of bayes rule on kinasese cplocalized with Aqp2

Sheet Summary
A1: PFAM-Gene Name | B1: Initial Probability | C1: Transcriptome | D1: Proteome | E1: Consensus Site | F1: AVP Regulation | G1: Aqp2 Colocalization
A2: MAPK1 | B2: =1/521 -> 0.0019193858 | C2: =VLOOKUP(A2,Transcriptome!B:L,11,FALSE) -> 0.0050105485 | D2: =VLOOKUP(A2,Proteome!B:I,8,FALSE) -> 0.0055901391 | E2: =VLOOKUP(A2,'Consensus Phospho site'!$B$2:$G$522,6,FALSE) -> 0.013914228 | F2: =VLOOKUP(A2,'AVP Regulation (PTM & Ca-cAMP'!B:K,10,FALSE) -> 0.023668125 | G2: =VLOOKUP(A2,'AQP2 Colocalization'!A:F,6,FALSE) -> 0.039314858
A3: MAPK3 | B3: =1/521 -> 0.0019193858 | C3: =VLOOKUP(A3,Transcriptome!B:L,11,FALSE) -> 0.0050105485 | D3: =VLOOKUP(A3,Proteome!B:I,8,FALSE) -> 0.0055901391 | E3: =VLOOKUP(A3,'Consensus Phospho site'!$B$2:$G$522,6,FALSE) -> 0.013914228 | F3: =VLOOKUP(A3,'AVP Regulation (PTM & Ca-cAMP'!B:K,10,FALSE) -> 0.023668125 | G3: =VLOOKUP(A3,'AQP2 Colocalization'!A:F,6,FALSE) -> 0.039314858
A4: MAPK14 | B4: =1/521 -> 0.0019193858 | C4: =VLOOKUP(A4,Transcriptome!B:L,11,FALSE) -> 0.0050105485 | D4: =VLOOKUP(A4,Proteome!B:I,8,FALSE) -> 0.0055901391 | E4: =VLOOKUP(A4,'Consensus Phospho site'!$B$2:$G$522,6,FALSE) -> 0.013914228 | F4: =VLOOKUP(A4,'AVP Regulation (PTM & Ca-cAMP'!B:K,10,FALSE) -> 0.023668125 | G4: =VLOOKUP(A4,'AQP2 Colocalization'!A:F,6,FALSE) -> 0.03494654
A5: GSK3A | B5: =1/521 -> 0.0019193858 | C5: =VLOOKUP(A5,Transcriptome!B:L,11,FALSE) -> 0.0036919831 | D5: =VLOOKUP(A5,Proteome!B:I,8,FALSE) -> 0.0041190498 | E5: =VLOOKUP(A5,'Consensus Phospho site'!$B$2:$G$522,6,FALSE) -> 0.010252589 | F5: =VLOOKUP(A5,'AVP Regulation (PTM & Ca-cAMP'!B:K,10,FALSE) -> 0.017439671 | G5: =VLOOKUP(A5,'AQP2 Colocalization'!A:F,6,FALSE) -> 0.012875041
A6: SRPK1 | B6: =1/521 -> 0.0019193858 | C6: =VLOOKUP(A6,Transcriptome!B:L,11,FALSE) -> 0.0050105485 | D6: =VLOOKUP(A6,Proteome!B:I,8,FALSE) -> 0.0055901391 | E6: =VLOOKUP(A6,'Consensus Phospho site'!$B$2:$G$522,6,FALSE) -> 0.013914228 | F6: =VLOOKUP(A6,'AVP Regulation (PTM & Ca-cAMP'!B:K,10,FALSE) -> 0.013148958 | G6: =VLOOKUP(A6,'AQP2 Colocalization'!A:F,6,FALSE) -> 0.019414745
A7: MAPK6 | B7: =1/521 -> 0.0019193858 | C7: =VLOOKUP(A7,Transcriptome!B:L,11,FALSE) -> 0.0050105485 | D7: =VLOOKUP(A7,Proteome!B:I,8,FALSE) -> 0.0055901391 | E7: =VLOOKUP(A7,'Consensus Phospho site'!$B$2:$G$522,6,FALSE) -> 0.013914228 | F7: =VLOOKUP(A7,'AVP Regulation (PTM & Ca-cAMP'!B:K,10,FALSE) -> 0.013148958 | G7: =VLOOKUP(A7,'AQP2 Colocalization'!A:F,6,FALSE) -> 0.0097073723
A8: CDK2 | B8: =1/521 -> 0.0019193858 | C8: =VLOOKUP(A8,Transcriptome!B:L,11,FALSE) -> 0.0050105485 | D8: =VLOOKUP(A8,Proteome!B:I,8,FALSE) -> 0.0055901391 | E8: =VLOOKUP(A8,'Consensus Phospho site'!$B$2:$G$522,6,FALSE) -> 0.013914228 | F8: =VLOOKUP(A8,'AVP Regulation (PTM & Ca-cAMP'!B:K,10,FALSE) -> 0.013148958 | G8: =VLOOKUP(A8,'AQP2 Colocalization'!A:F,6,FALSE) -> 0.021841588
A9: CDK4 | B9: =1/521 -> 0.0019193858 | C9: =VLOOKUP(A9,Transcriptome!B:L,11,FALSE) -> 0.0050105485 | D9: =VLOOKUP(A9,Proteome!B:I,8,FALSE) -> 0.0055901391 | E9: =VLOOKUP(A9,'Consensus Phospho site'!$B$2:$G$522,6,FALSE) -> 0.013914228 | F9: =VLOOKUP(A9,'AVP Regulation (PTM & Ca-cAMP'!B:K,10,FALSE) -> 0.013148958 | G9: =VLOOKUP(A9,'AQP2 Colocalization'!A:F,6,FALSE) -> 0.021841588
A10: NLK | B10: =1/521 -> 0.0019193858 | C10: =VLOOKUP(A10,Transcriptome!B:L,11,FALSE) -> 0.0050105485 | D10: =VLOOKUP(A10,Proteome!B:I,8,FALSE) -> 0.0055901391 | E10: =VLOOKUP(A10,'Consensus Phospho site'!$B$2:$G$522,6,FALSE) -> 0.013914228 | F10: =VLOOKUP(A10,'AVP Regulation (PTM & Ca-cAMP'!B:K,10,FALSE) -> 0.013148958 | G10: =VLOOKUP(A10,'AQP2 Colocalization'!A:F,6,FALSE) -> 0.019414745
A11: GSK3B | B11: =1/521 -> 0.0019193858 | C11: =VLOOKUP(A11,Transcriptome!B:L,11,FALSE) -> 0.0050105485 | D11: =VLOOKUP(A11,Proteome!B:I,8,FALSE) -> 0.0055901391 | E11: =VLOOKUP(A11,'Consensus Phospho site'!$B$2:$G$522,6,FALSE) -> 0.013914228 | F11: =VLOOKUP(A11,'AVP Regulation (PTM & Ca-cAMP'!B:K,10,FALSE) -> 0.013148958 | G11: =VLOOKUP(A11,'AQP2 Colocalization'!A:F,6,FALSE) -> 0.019414745
A12: CDK9 | B12: =1/521 -> 0.0019193858 | C12: =VLOOKUP(A12,Transcriptome!B:L,11,FALSE) -> 0.0050105485 | D12: =VLOOKUP(A12,Proteome!B:I,8,FALSE) -> 0.0055901391 | E12: =VLOOKUP(A12,'Consensus Phospho site'!$B$2:$G$522,6,FALSE) -> 0.013914228 | F12: =VLOOKUP(A12,'AVP Regulation (PTM & Ca-cAMP'!B:K,10,FALSE) -> 0.013148958 | G12: =VLOOKUP(A12,'AQP2 Colocalization'!A:F,6,FALSE) -> 0.019414745
A13: CDK6 | B13: =1/521 -> 0.0019193858 | C13: =VLOOKUP(A13,Transcriptome!B:L,11,FALSE) -> 0.0050105485 | D13: =VLOOKUP(A13,Proteome!B:I,8,FALSE) -> 0.0055901391 | E13: =VLOOKUP(A13,'Consensus Phospho site'!$B$2:$G$522,6,FALSE) -> 0.013914228 | F13: =VLOOKUP(A13,'AVP Regulation (PTM & Ca-cAMP'!B:K,10,FALSE) -> 0.013148958 | G13: =VLOOKUP(A13,'AQP2 Colocalization'!A:F,6,FALSE) -> 0.019414745
... A522: PRKACG | B522: =1/521 -> 0.0019193858 | C522: =VLOOKUP(A522,Transcriptome!B:L,11,FALSE) -> 0.00052742616 | D522: =VLOOKUP(A522,Proteome!B:I,8,FALSE) -> 0.00030970299 | E522: =VLOOKUP(A522,'Consensus Phospho site'!$B$2:$G$522,6,FALSE) -> 8.5652371e-05 | F522: =VLOOKUP(A522,'AVP Regulation (PTM & Ca-cAMP'!B:K,10,FALSE) -> 1.6188314e-05 | G522: =VLOOKUP(A522,'AQP2 Colocalization'!A:F,6,FALSE) -> 1.1951212e-05

Sheet Transcriptome
A1: Family | B1: PFAM-Gene Name | C1: mpkCCD database | D1: Probability | E1: Information | F1: Clone 11 Microarray signal | G1: Clone11_signal | H1: Probability Expressed | J1: Partial Bayes probability | K1: SUM | L1: Bayes Probability | M1: partial information | N1: Information
A2: CAMK | B2: CAMK2B | C2: Camk2b | D2: =1/521 -> 0.0019193858 | E2: =-LOG(D2,2) -> 9.0251396 | F2: 20.98 | G2: 20.98 | H2: =IF(G2>1,0.95,IF(G2<0.6, 0.1, 0.7)) -> 0.95 | J2: =D2*H2 -> 0.0018234165 | K2: =SUM(J$2:J$523) -> 0.36391555 | L2: =J2/K2 -> 0.0050105485 | M2: =L2*-LOG(L2,2) -> 0.038284678 | N2: =SUM(M2:M523) -> 8.3258114
A3: Tyr | B3: DDR1 | C3: Ddr1 | D3: =1/521 -> 0.0019193858 | F3: 7.54 | G3: 7.54 | H3: =IF(G3>1,0.95,IF(G3<0.6, 0.1, 0.7)) -> 0.95 | J3: =D3*H3 -> 0.0018234165 | K3: =SUM(J$2:J$523) -> 0.36391555 | L3: =J3/K3 -> 0.0050105485 | M3: =L3*-LOG(L3,2) -> 0.038284678
A4: AGC | B4: PRKCI | C4: Prkci | D4: =1/521 -> 0.0019193858 | F4: 7.37 | G4: 7.37 | H4: =IF(G4>1,0.95,IF(G4<0.6, 0.1, 0.7)) -> 0.95 | J4: =D4*H4 -> 0.0018234165 | K4: =SUM(J$2:J$523) -> 0.36391555 | L4: =J4/K4 -> 0.0050105485 | M4: =L4*-LOG(L4,2) -> 0.038284678
A5: Other | B5: WNK1 | C5: Wnk1 | D5: =1/521 -> 0.0019193858 | F5: 6.7 | G5: 6.7 | H5: =IF(G5>1,0.95,IF(G5<0.6, 0.1, 0.7)) -> 0.95 | J5: =D5*H5 -> 0.0018234165 | K5: =SUM(J$2:J$523) -> 0.36391555 | L5: =J5/K5 -> 0.0050105485 | M5: =L5*-LOG(L5,2) -> 0.038284678
A6: CAMK | B6: MKNK2 | C6: Mknk2 | D6: =1/521 -> 0.0019193858 | F6: 5.26 | G6: 5.26 | H6: =IF(G6>1,0.95,IF(G6<0.6, 0.1, 0.7)) -> 0.95 | J6: =D6*H6 -> 0.0018234165 | K6: =SUM(J$2:J$523) -> 0.36391555 | L6: =J6/K6 -> 0.0050105485 | M6: =L6*-LOG(L6,2) -> 0.038284678
A7: CMGC | B7: HIPK3 | C7: Hipk3 | D7: =1/521 -> 0.0019193858 | F7: 4.86 | G7: 4.86 | H7: =IF(G7>1,0.95,IF(G7<0.6, 0.1, 0.7)) -> 0.95 | J7: =D7*H7 -> 0.0018234165 | K7: =SUM(J$2:J$523) -> 0.36391555 | L7: =J7/K7 -> 0.0050105485 | M7: =L7*-LOG(L7,2) -> 0.038284678
A8: CK1 | B8: CSNK1A1 | C8: Csnk1a1 | D8: =1/521 -> 0.0019193858 | F8: 4.49 | G8: 4.49 | H8: =IF(G8>1,0.95,IF(G8<0.6, 0.1, 0.7)) -> 0.95 | J8: =D8*H8 -> 0.0018234165 | K8: =SUM(J$2:J$523) -> 0.36391555 | L8: =J8/K8 -> 0.0050105485 | M8: =L8*-LOG(L8,2) -> 0.038284678
A9: CMGC | B9: CDK4 | C9: Cdk4 | D9: =1/521 -> 0.0019193858 | F9: 4.46 | G9: 4.46 | H9: =IF(G9>1,0.95,IF(G9<0.6, 0.1, 0.7)) -> 0.95 | J9: =D9*H9 -> 0.0018234165 | K9: =SUM(J$2:J$523) -> 0.36391555 | L9: =J9/K9 -> 0.0050105485 | M9: =L9*-LOG(L9,2) -> 0.038284678
A10: TKL | B10: TGFBR2 | C10: Tgfbr2 | D10: =1/521 -> 0.0019193858 | F10: 4.41 | G10: 4.41 | H10: =IF(G10>1,0.95,IF(G10<0.6, 0.1, 0.7)) -> 0.95 | J10: =D10*H10 -> 0.0018234165 | K10: =SUM(J$2:J$523) -> 0.36391555 | L10: =J10/K10 -> 0.0050105485 | M10: =L10*-LOG(L10,2) -> 0.038284678
A11: CMGC | B11: MAPK1 | C11: Mapk1 | D11: =1/521 -> 0.0019193858 | F11: 4.23 | G11: 4.23 | H11: =IF(G11>1,0.95,IF(G11<0.6, 0.1, 0.7)) -> 0.95 | J11: =D11*H11 -> 0.0018234165 | K11: =SUM(J$2:J$523) -> 0.36391555 | L11: =J11/K11 -> 0.0050105485 | M11: =L11*-LOG(L11,2) -> 0.038284678
A12: CMGC | B12: GSK3B | C12: Gsk3b | D12: =1/521 -> 0.0019193858 | F12: 4.19 | G12: 4.19 | H12: =IF(G12>1,0.95,IF(G12<0.6, 0.1, 0.7)) -> 0.95 | J12: =D12*H12 -> 0.0018234165 | K12: =SUM(J$2:J$523) -> 0.36391555 | L12: =J12/K12 -> 0.0050105485 | M12: =L12*-LOG(L12,2) -> 0.038284678
A13: Tyr | B13: ERBB3 | C13: Erbb3 | D13: =1/521 -> 0.0019193858 | F13: 4.09 | G13: 4.09 | H13: =IF(G13>1,0.95,IF(G13<0.6, 0.1, 0.7)) -> 0.95 | J13: =D13*H13 -> 0.0018234165 | K13: =SUM(J$2:J$523) -> 0.36391555 | L13: =J13/K13 -> 0.0050105485 | M13: =L13*-LOG(L13,2) -> 0.038284678
A14: STE | B14: MAP4K3 | C14: Map4k3 | D14: =1/521 -> 0.0019193858 | F14: 4.06 | G14: 4.06 | H14: =IF(G14>1,0.95,IF(G14<0.6, 0.1, 0.7)) -> 0.95 | J14: =D14*H14 -> 0.0018234165 | K14: =SUM(J$2:J$523) -> 0.36391555 | L14: =J14/K14 -> 0.0050105485 | M14: =L14*-LOG(L14,2) -> 0.038284678
... A255: Other | B255: MLKL | C255: Mlkl | D255: =1/521 -> 0.0019193858 | F255: 0.2 | G255: 0.2 | H255: =IF(G255>1,0.95,IF(G255<0.6, 0.1, 0.7)) -> 0.1 | J255: =D255*H255 -> 0.00019193858 | K255: =SUM(J$2:J$523) -> 0.36391555 | L255: =J255/K255 -> 0.00052742616 | M255: =L255*-LOG(L255,2) -> 0.005743008
A256: Tyr | B256: AATK | C256: #N/A | D256: =1/521 -> 0.0019193858 | F256: #N/A | G256: 0 | H256: =IF(G256>1,0.95,IF(G256<0.6, 0.1, 0.7)) -> 0.1 | J256: =D256*H256 -> 0.00019193858 | K256: =SUM(J$2:J$523) -> 0.36391555 | L256: =J256/K256 -> 0.00052742616 | M256: =L256*-LOG(L256,2) -> 0.005743008
A257: TKL | B257: ACVR1C | C257: #N/A | D257: =1/521 -> 0.0019193858 | F257: #N/A | G257: 0 | H257: =IF(G257>1,0.95,IF(G257<0.6, 0.1, 0.7)) -> 0.1 | J257: =D257*H257 -> 0.00019193858 | K257: =SUM(J$2:J$523) -> 0.36391555 | L257: =J257/K257 -> 0.00052742616 | M257: =L257*-LOG(L257,2) -> 0.005743008
A258: TKL | B258: ACVR2B | C258: #N/A | D258: =1/521 -> 0.0019193858 | F258: #N/A | G258: 0 | H258: =IF(G258>1,0.95,IF(G258<0.6, 0.1, 0.7)) -> 0.1 | J258: =D258*H258 -> 0.00019193858 | K258: =SUM(J$2:J$523) -> 0.36391555 | L258: =J258/K258 -> 0.00052742616 | M258: =L258*-LOG(L258,2) -> 0.005743008
A259: TKL | B259: ACVRL1 | C259: #N/A | D259: =1/521 -> 0.0019193858 | F259: #N/A | G259: 0 | H259: =IF(G259>1,0.95,IF(G259<0.6, 0.1, 0.7)) -> 0.1 | J259: =D259*H259 -> 0.00019193858 | K259: =SUM(J$2:J$523) -> 0.36391555 | L259: =J259/K259 -> 0.00052742616 | M259: =L259*-LOG(L259,2) -> 0.005743008
A260: Atypical | B260: ADCK1 | C260: #N/A | D260: =1/521 -> 0.0019193858 | F260: #N/A | G260: 0 | H260: =IF(G260>1,0.95,IF(G260<0.6, 0.1, 0.7)) -> 0.1 | J260: =D260*H260 -> 0.00019193858 | K260: =SUM(J$2:J$523) -> 0.36391555 | L260: =J260/K260 -> 0.00052742616 | M260: =L260*-LOG(L260,2) -> 0.005743008
A261: Atypical | B261: ADCK2 | C261: #N/A | D261: =1/521 -> 0.0019193858 | F261: #N/A | G261: 0 | H261: =IF(G261>1,0.95,IF(G261<0.6, 0.1, 0.7)) -> 0.1 | J261: =D261*H261 -> 0.00019193858 | K261: =SUM(J$2:J$523) -> 0.36391555 | L261: =J261/K261 -> 0.00052742616 | M261: =L261*-LOG(L261,2) -> 0.005743008
A262: Atypical | B262: ADCK3 | C262: #N/A | D262: =1/521 -> 0.0019193858 | F262: #N/A | G262: 0 | H262: =IF(G262>1,0.95,IF(G262<0.6, 0.1, 0.7)) -> 0.1 | J262: =D262*H262 -> 0.00019193858 | K262: =SUM(J$2:J$523) -> 0.36391555 | L262: =J262/K262 -> 0.00052742616 | M262: =L262*-LOG(L262,2) -> 0.005743008
A263: Atypical | B263: ADCK4 | C263: #N/A | D263: =1/521 -> 0.0019193858 | F263: #N/A | G263: 0 | H263: =IF(G263>1,0.95,IF(G263<0.6, 0.1, 0.7)) -> 0.1 | J263: =D263*H263 -> 0.00019193858 | K263: =SUM(J$2:J$523) -> 0.36391555 | L263: =J263/K263 -> 0.00052742616 | M263: =L263*-LOG(L263,2) -> 0.005743008
A264: AGC | B264: ADRBK2 | C264: #N/A | D264: =1/521 -> 0.0019193858 | F264: #N/A | G264: 0 | H264: =IF(G264>1,0.95,IF(G264<0.6, 0.1, 0.7)) -> 0.1 | J264: =D264*H264 -> 0.00019193858 | K264: =SUM(J$2:J$523) -> 0.36391555 | L264: =J264/K264 -> 0.00052742616 | M264: =L264*-LOG(L264,2) -> 0.005743008
A265: Tyr | B265: ALK | C265: #N/A | D265: =1/521 -> 0.0019193858 | F265: #N/A | G265: 0 | H265: =IF(G265>1,0.95,IF(G265<0.6, 0.1, 0.7)) -> 0.1 | J265: =D265*H265 -> 0.00019193858 | K265: =SUM(J$2:J$523) -> 0.36391555 | L265: =J265/K265 -> 0.00052742616 | M265: =L265*-LOG(L265,2) -> 0.005743008
A266: Atypical | B266: ALPK1 | C266: #N/A | D266: =1/521 -> 0.0019193858 | F266: #N/A | G266: 0 | H266: =IF(G266>1,0.95,IF(G266<0.6, 0.1, 0.7)) -> 0.1 | J266: =D266*H266 -> 0.00019193858 | K266: =SUM(J$2:J$523) -> 0.36391555 | L266: =J266/K266 -> 0.00052742616 | M266: =L266*-LOG(L266,2) -> 0.005743008
A267: Atypical | B267: ALPK2 | C267: #N/A | D267: =1/521 -> 0.0019193858 | F267: #N/A | G267: 0 | H267: =IF(G267>1,0.95,IF(G267<0.6, 0.1, 0.7)) -> 0.1 | J267: =D267*H267 -> 0.00019193858 | K267: =SUM(J$2:J$523) -> 0.36391555 | L267: =J267/K267 -> 0.00052742616 | M267: =L267*-LOG(L267,2) -> 0.005743008
... A462: Other | B462: SGK071 | C462: #N/A | D462: =1/521 -> 0.0019193858 | F462: #N/A | G462: 0 | H462: =IF(G462>1,0.95,IF(G462<0.6, 0.1, 0.7)) -> 0.1 | J462: =D462*H462 -> 0.00019193858 | K462: =SUM(J$2:J$523) -> 0.36391555 | L462: =J462/K462 -> 0.00052742616 | M462: =L462*-LOG(L462,2) -> 0.005743008
A463: AGC | B463: SGK1 | C463: #N/A | D463: =1/521 -> 0.0019193858 | E463: =-LOG(D463,2) -> 9.0251396 | F463: #N/A | G463: 0 | H463: =IF(G463>1,0.95,IF(G463<0.6, 0.1, 0.7)) -> 0.1 | J463: =D463*H463 -> 0.00019193858 | K463: =SUM(J$2:J$523) -> 0.36391555 | L463: =J463/K463 -> 0.00052742616 | M463: =L463*-LOG(L463,2) -> 0.005743008
A464: Other | B464: SGK110 | C464: #N/A | D464: =1/521 -> 0.0019193858 | F464: #N/A | G464: 0 | H464: =IF(G464>1,0.95,IF(G464<0.6, 0.1, 0.7)) -> 0.1 | J464: =D464*H464 -> 0.00019193858 | K464: =SUM(J$2:J$523) -> 0.36391555 | L464: =J464/K464 -> 0.00052742616 | M464: =L464*-LOG(L464,2) -> 0.005743008
A465: AGC | B465: SGK2 | C465: #N/A | D465: =1/521 -> 0.0019193858 | F465: #N/A | G465: 0 | H465: =IF(G465>1,0.95,IF(G465<0.6, 0.1, 0.7)) -> 0.1 | J465: =D465*H465 -> 0.00019193858 | K465: =SUM(J$2:J$523) -> 0.36391555 | L465: =J465/K465 -> 0.00052742616 | M465: =L465*-LOG(L465,2) -> 0.005743008
A466: Other | B466: SGK223 | C466: #N/A | D466: =1/521 -> 0.0019193858 | F466: #N/A | G466: 0 | H466: =IF(G466>1,0.95,IF(G466<0.6, 0.1, 0.7)) -> 0.1 | J466: =D466*H466 -> 0.00019193858 | K466: =SUM(J$2:J$523) -> 0.36391555 | L466: =J466/K466 -> 0.00052742616 | M466: =L466*-LOG(L466,2) -> 0.005743008
A467: Other | B467: SGK494 | C467: #N/A | D467: =1/521 -> 0.0019193858 | F467: #N/A | G467: 0 | H467: =IF(G467>1,0.95,IF(G467<0.6, 0.1, 0.7)) -> 0.1 | J467: =D467*H467 -> 0.00019193858 | K467: =SUM(J$2:J$523) -> 0.36391555 | L467: =J467/K467 -> 0.00052742616 | M467: =L467*-LOG(L467,2) -> 0.005743008
A468: CAMK | B468: SIK1 | C468: #N/A | D468: =1/521 -> 0.0019193858 | F468: #N/A | G468: 0 | H468: =IF(G468>1,0.95,IF(G468<0.6, 0.1, 0.7)) -> 0.1 | J468: =D468*H468 -> 0.00019193858 | K468: =SUM(J$2:J$523) -> 0.36391555 | L468: =J468/K468 -> 0.00052742616 | M468: =L468*-LOG(L468,2) -> 0.005743008
A469: CAMK | B469: SIK2 | C469: #N/A | D469: =1/521 -> 0.0019193858 | F469: #N/A | G469: 0 | H469: =IF(G469>1,0.95,IF(G469<0.6, 0.1, 0.7)) -> 0.1 | J469: =D469*H469 -> 0.00019193858 | K469: =SUM(J$2:J$523) -> 0.36391555 | L469: =J469/K469 -> 0.00052742616 | M469: =L469*-LOG(L469,2) -> 0.005743008
A470: CAMK | B470: SIK3 | C470: #N/A | D470: =1/521 -> 0.0019193858 | F470: #N/A | G470: 0 | H470: =IF(G470>1,0.95,IF(G470<0.6, 0.1, 0.7)) -> 0.1 | J470: =D470*H470 -> 0.00019193858 | K470: =SUM(J$2:J$523) -> 0.36391555 | L470: =J470/K470 -> 0.00052742616 | M470: =L470*-LOG(L470,2) -> 0.005743008
A471: Atypical | B471: SMG1 | C471: #N/A | D471: =1/521 -> 0.0019193858 | F471: #N/A | G471: 0 | H471: =IF(G471>1,0.95,IF(G471<0.6, 0.1, 0.7)) -> 0.1 | J471: =D471*H471 -> 0.00019193858 | K471: =SUM(J$2:J$523) -> 0.36391555 | L471: =J471/K471 -> 0.00052742616 | M471: =L471*-LOG(L471,2) -> 0.005743008
A472: Tyr | B472: Smok1 | C472: #N/A | D472: =1/521 -> 0.0019193858 | F472: #N/A | G472: 0 | H472: =IF(G472>1,0.95,IF(G472<0.6, 0.1, 0.7)) -> 0.1 | J472: =D472*H472 -> 0.00019193858 | K472: =SUM(J$2:J$523) -> 0.36391555 | L472: =J472/K472 -> 0.00052742616 | M472: =L472*-LOG(L472,2) -> 0.005743008
A473: CAMK | B473: Smok2a | C473: #N/A | D473: =1/521 -> 0.0019193858 | F473: #N/A | G473: 0 | H473: =IF(G473>1,0.95,IF(G473<0.6, 0.1, 0.7)) -> 0.1 | J473: =D473*H473 -> 0.00019193858 | K473: =SUM(J$2:J$523) -> 0.36391555 | L473: =J473/K473 -> 0.00052742616 | M473: =L473*-LOG(L473,2) -> 0.005743008
A474: CAMK | B474: Smok2b | C474: #N/A | D474: =1/521 -> 0.0019193858 | F474: #N/A | G474: 0 | H474: =IF(G474>1,0.95,IF(G474<0.6, 0.1, 0.7)) -> 0.1 | J474: =D474*H474 -> 0.00019193858 | K474: =SUM(J$2:J$523) -> 0.36391555 | L474: =J474/K474 -> 0.00052742616 | M474: =L474*-LOG(L474,2) -> 0.005743008
...

Sheet Proteome
A1: Family | B1: PFAM-Gene Name | C1: mpkCCD proteome | D1: mpkCCD proteome | E1: Expressed Probability | F1: Prior Probability | G1: Partial Bayes Probability | H1: SUM | I1: Bayes Probability | J1: Partial Information | K1: Shannon Information | P1: 348 Kinases
A2: Other | B2: AAK1 | C2: Aak1 | D2: Aak1 | E2: 0.95 | F2: =VLOOKUP(B2,Transcriptome!B:L,11,FALSE) -> 0.0050105485 | G2: =E2*F2 -> 0.0047600211 | H2: =SUM($G$2:$G$522) -> 0.85150316 | I2: =G2/H2 -> 0.0055901391 | J2: =-I2*LOG(I2,2) -> 0.041830452 | K2: =SUM($J$2:$J$522) -> 8.2281845
A3: Tyr | B3: ABL1 | C3: Abl1 | D3: Abl1 | E3: 0.95 | F3: =VLOOKUP(B3,Transcriptome!B:L,11,FALSE) -> 0.0036919831 | G3: =E3*F3 -> 0.003507384 | H3: =SUM($G$2:$G$522) -> 0.85150316 | I3: =G3/H3 -> 0.0041190498 | J3: =-I3*LOG(I3,2) -> 0.032637179 | K3: =SUM($J$2:$J$522) -> 8.2281845
A4: Tyr | B4: ABL2 | C4: Abl2 | D4: Abl2 | E4: 0.95 | F4: =VLOOKUP(B4,Transcriptome!B:L,11,FALSE) -> 0.0036919831 | G4: =E4*F4 -> 0.003507384 | H4: =SUM($G$2:$G$522) -> 0.85150316 | I4: =G4/H4 -> 0.0041190498 | J4: =-I4*LOG(I4,2) -> 0.032637179 | K4: =SUM($J$2:$J$522) -> 8.2281845
A5: TKL | B5: ACVR2A | C5: Acvr2a | D5: Acvr2a | E5: 0.95 | F5: =VLOOKUP(B5,Transcriptome!B:L,11,FALSE) -> 0.0050105485 | G5: =E5*F5 -> 0.0047600211 | H5: =SUM($G$2:$G$522) -> 0.85150316 | I5: =G5/H5 -> 0.0055901391 | J5: =-I5*LOG(I5,2) -> 0.041830452 | K5: =SUM($J$2:$J$522) -> 8.2281845
A6: Atypical | B6: ADCK1 | C6: Adck1 | D6: Adck1 | E6: 0.95 | F6: =VLOOKUP(B6,Transcriptome!B:L,11,FALSE) -> 0.00052742616 | G6: =E6*F6 -> 0.00050105485 | H6: =SUM($G$2:$G$522) -> 0.85150316 | I6: =G6/H6 -> 0.00058843569 | J6: =-I6*LOG(I6,2) -> 0.006314402 | K6: =SUM($J$2:$J$522) -> 8.2281845
A7: Atypical | B7: ADCK5 | C7: Adck5 | D7: Adck5 | E7: 0.95 | F7: =VLOOKUP(B7,Transcriptome!B:L,11,FALSE) -> 0.0036919831 | G7: =E7*F7 -> 0.003507384 | H7: =SUM($G$2:$G$522) -> 0.85150316 | I7: =G7/H7 -> 0.0041190498 | J7: =-I7*LOG(I7,2) -> 0.032637179 | K7: =SUM($J$2:$J$522) -> 8.2281845
A8: AGC | B8: ADRBK1 | C8: Adrbk1 | D8: Adrbk1 | E8: 0.95 | F8: =VLOOKUP(B8,Transcriptome!B:L,11,FALSE) -> 0.0036919831 | G8: =E8*F8 -> 0.003507384 | H8: =SUM($G$2:$G$522) -> 0.85150316 | I8: =G8/H8 -> 0.0041190498 | J8: =-I8*LOG(I8,2) -> 0.032637179 | K8: =SUM($J$2:$J$522) -> 8.2281845
A9: AGC | B9: ADRBK2 | C9: Adrbk2 | D9: Adrbk2 | E9: 0.95 | F9: =VLOOKUP(B9,Transcriptome!B:L,11,FALSE) -> 0.00052742616 | G9: =E9*F9 -> 0.00050105485 | H9: =SUM($G$2:$G$522) -> 0.85150316 | I9: =G9/H9 -> 0.00058843569 | J9: =-I9*LOG(I9,2) -> 0.006314402 | K9: =SUM($J$2:$J$522) -> 8.2281845
A10: AGC | B10: AKT1 | C10: Akt1 | D10: Akt1 | E10: 0.95 | F10: =VLOOKUP(B10,Transcriptome!B:L,11,FALSE) -> 0.0050105485 | G10: =E10*F10 -> 0.0047600211 | H10: =SUM($G$2:$G$522) -> 0.85150316 | I10: =G10/H10 -> 0.0055901391 | J10: =-I10*LOG(I10,2) -> 0.041830452 | K10: =SUM($J$2:$J$522) -> 8.2281845
A11: AGC | B11: AKT2 | C11: Akt2 | D11: Akt2 | E11: 0.95 | F11: =VLOOKUP(B11,Transcriptome!B:L,11,FALSE) -> 0.0036919831 | G11: =E11*F11 -> 0.003507384 | H11: =SUM($G$2:$G$522) -> 0.85150316 | I11: =G11/H11 -> 0.0041190498 | J11: =-I11*LOG(I11,2) -> 0.032637179 | K11: =SUM($J$2:$J$522) -> 8.2281845
A12: AGC | B12: AKT3 | C12: Akt3 | D12: Akt3 | E12: 0.95 | F12: =VLOOKUP(B12,Transcriptome!B:L,11,FALSE) -> 0.0036919831 | G12: =E12*F12 -> 0.003507384 | H12: =SUM($G$2:$G$522) -> 0.85150316 | I12: =G12/H12 -> 0.0041190498 | J12: =-I12*LOG(I12,2) -> 0.032637179 | K12: =SUM($J$2:$J$522) -> 8.2281845
A13: Tyr | B13: ALK | C13: Alk | D13: Alk | E13: 0.95 | F13: =VLOOKUP(B13,Transcriptome!B:L,11,FALSE) -> 0.00052742616 | G13: =E13*F13 -> 0.00050105485 | H13: =SUM($G$2:$G$522) -> 0.85150316 | I13: =G13/H13 -> 0.00058843569 | J13: =-I13*LOG(I13,2) -> 0.006314402 | K13: =SUM($J$2:$J$522) -> 8.2281845
... A349: Tyr | B349: YES1 | C349: Yes1 | D349: Yes1 | E349: 0.95 | F349: =VLOOKUP(B349,Transcriptome!B:L,11,FALSE) -> 0.00052742616 | G349: =E349*F349 -> 0.00050105485 | H349: =SUM($G$2:$G$522) -> 0.85150316 | I349: =G349/H349 -> 0.00058843569 | J349: =-I349*LOG(I349,2) -> 0.006314402 | K349: =SUM($J$2:$J$522) -> 8.2281845
A350: Tyr | B350: AATK | C350: #N/A | D350: #N/A | E350: 0.5 | F350: =VLOOKUP(B350,Transcriptome!B:L,11,FALSE) -> 0.00052742616 | G350: =E350*F350 -> 0.00026371308 | H350: =SUM($G$2:$G$522) -> 0.85150316 | I350: =G350/H350 -> 0.00030970299 | J350: =-I350*LOG(I350,2) -> 0.0036101542 | K350: =SUM($J$2:$J$522) -> 8.2281845
A351: TKL | B351: ACVR1 | C351: #N/A | D351: #N/A | E351: 0.5 | F351: =VLOOKUP(B351,Transcriptome!B:L,11,FALSE) -> 0.00052742616 | G351: =E351*F351 -> 0.00026371308 | H351: =SUM($G$2:$G$522) -> 0.85150316 | I351: =G351/H351 -> 0.00030970299 | J351: =-I351*LOG(I351,2) -> 0.0036101542 | K351: =SUM($J$2:$J$522) -> 8.2281845
A352: TKL | B352: ACVR1B | C352: #N/A | D352: #N/A | E352: 0.5 | F352: =VLOOKUP(B352,Transcriptome!B:L,11,FALSE) -> 0.0050105485 | G352: =E352*F352 -> 0.0025052743 | H352: =SUM($G$2:$G$522) -> 0.85150316 | I352: =G352/H352 -> 0.0029421785 | J352: =-I352*LOG(I352,2) -> 0.024740483 | K352: =SUM($J$2:$J$522) -> 8.2281845
A353: TKL | B353: ACVR1C | C353: #N/A | D353: #N/A | E353: 0.5 | F353: =VLOOKUP(B353,Transcriptome!B:L,11,FALSE) -> 0.00052742616 | G353: =E353*F353 -> 0.00026371308 | H353: =SUM($G$2:$G$522) -> 0.85150316 | I353: =G353/H353 -> 0.00030970299 | J353: =-I353*LOG(I353,2) -> 0.0036101542 | K353: =SUM($J$2:$J$522) -> 8.2281845
A354: TKL | B354: ACVR2B | C354: #N/A | D354: #N/A | E354: 0.5 | F354: =VLOOKUP(B354,Transcriptome!B:L,11,FALSE) -> 0.00052742616 | G354: =E354*F354 -> 0.00026371308 | H354: =SUM($G$2:$G$522) -> 0.85150316 | I354: =G354/H354 -> 0.00030970299 | J354: =-I354*LOG(I354,2) -> 0.0036101542 | K354: =SUM($J$2:$J$522) -> 8.2281845
A355: TKL | B355: ACVRL1 | C355: #N/A | D355: #N/A | E355: 0.5 | F355: =VLOOKUP(B355,Transcriptome!B:L,11,FALSE) -> 0.00052742616 | G355: =E355*F355 -> 0.00026371308 | H355: =SUM($G$2:$G$522) -> 0.85150316 | I355: =G355/H355 -> 0.00030970299 | J355: =-I355*LOG(I355,2) -> 0.0036101542 | K355: =SUM($J$2:$J$522) -> 8.2281845
A356: Atypical | B356: ADCK2 | C356: #N/A | D356: #N/A | E356: 0.5 | F356: =VLOOKUP(B356,Transcriptome!B:L,11,FALSE) -> 0.00052742616 | G356: =E356*F356 -> 0.00026371308 | H356: =SUM($G$2:$G$522) -> 0.85150316 | I356: =G356/H356 -> 0.00030970299 | J356: =-I356*LOG(I356,2) -> 0.0036101542 | K356: =SUM($J$2:$J$522) -> 8.2281845
A357: Atypical | B357: ADCK3 | C357: #N/A | D357: #N/A | E357: 0.5 | F357: =VLOOKUP(B357,Transcriptome!B:L,11,FALSE) -> 0.00052742616 | G357: =E357*F357 -> 0.00026371308 | H357: =SUM($G$2:$G$522) -> 0.85150316 | I357: =G357/H357 -> 0.00030970299 | J357: =-I357*LOG(I357,2) -> 0.0036101542 | K357: =SUM($J$2:$J$522) -> 8.2281845
A358: Atypical | B358: ADCK4 | C358: #N/A | D358: #N/A | E358: 0.5 | F358: =VLOOKUP(B358,Transcriptome!B:L,11,FALSE) -> 0.00052742616 | G358: =E358*F358 -> 0.00026371308 | H358: =SUM($G$2:$G$522) -> 0.85150316 | I358: =G358/H358 -> 0.00030970299 | J358: =-I358*LOG(I358,2) -> 0.0036101542 | K358: =SUM($J$2:$J$522) -> 8.2281845
A359: Atypical | B359: ALPK1 | C359: #N/A | D359: #N/A | E359: 0.5 | F359: =VLOOKUP(B359,Transcriptome!B:L,11,FALSE) -> 0.00052742616 | G359: =E359*F359 -> 0.00026371308 | H359: =SUM($G$2:$G$522) -> 0.85150316 | I359: =G359/H359 -> 0.00030970299 | J359: =-I359*LOG(I359,2) -> 0.0036101542 | K359: =SUM($J$2:$J$522) -> 8.2281845
A360: TKL | B360: AMHR2 | C360: #N/A | D360: #N/A | E360: 0.5 | F360: =VLOOKUP(B360,Transcriptome!B:L,11,FALSE) -> 0.00052742616 | G360: =E360*F360 -> 0.00026371308 | H360: =SUM($G$2:$G$522) -> 0.85150316 | I360: =G360/H360 -> 0.00030970299 | J360: =-I360*LOG(I360,2) -> 0.0036101542 | K360: =SUM($J$2:$J$522) -> 8.2281845
A361: TKL | B361: ANKK1 | C361: #N/A | D361: #N/A | E361: 0.5 | F361: =VLOOKUP(B361,Transcriptome!B:L,11,FALSE) -> 0.00052742616 | G361: =E361*F361 -> 0.00026371308 | H361: =SUM($G$2:$G$522) -> 0.85150316 | I361: =G361/H361 -> 0.00030970299 | J361: =-I361*LOG(I361,2) -> 0.0036101542 | K361: =SUM($J$2:$J$522) -> 8.2281845
... A522: Tyr | B522: ZAP70 | C522: #N/A | D522: #N/A | E522: 0.5 | F522: =VLOOKUP(B522,Transcriptome!B:L,11,FALSE) -> 0.00052742616 | G522: =E522*F522 -> 0.00026371308 | H522: =SUM($G$2:$G$522) -> 0.85150316 | I522: =G522/H522 -> 0.00030970299 | J522: =-I522*LOG(I522,2) -> 0.0036101542 | K522: =SUM($J$2:$J$522) -> 8.2281845

Sheet Consensus Phospho site
A1: Family | B1: PFAM-Gene Name | C1: Prior Probability | D1: Consensus Site Probability | E1: Partial Bayes Probability | F1: SUM | G1: Bayes Probability | H1: Partial Information | I1: Shannon Information | K1: Kinase Family | L1: Probability @Aqp261p
A2: CMGC | B2: CLK1 | C2: =VLOOKUP(B2,Proteome!B:I,8,FALSE) -> 0.0055901391 | D2: =VLOOKUP(A2,$K$2:$L$12,2,FALSE) -> 0.9 | E2: =C2*D2 -> 0.0050311252 | F2: =SUM($E$2:$E$522) -> 0.36158134 | G2: =E2/F2 -> 0.013914228 | H2: =-G2*LOG(G2,2) -> 0.085813152 | I2: =SUM($H$2:$H$522) -> 7.7265767 | K2: AGC | L2: 0.1
A3: CMGC | B3: GSK3B | C3: =VLOOKUP(B3,Proteome!B:I,8,FALSE) -> 0.0055901391 | D3: =VLOOKUP(A3,$K$2:$L$12,2,FALSE) -> 0.9 | E3: =C3*D3 -> 0.0050311252 | F3: =SUM($E$2:$E$522) -> 0.36158134 | G3: =E3/F3 -> 0.013914228 | H3: =-G3*LOG(G3,2) -> 0.085813152 | I3: =SUM($H$2:$H$522) -> 7.7265767 | K3: CAMK | L3: 0.1
A4: CMGC | B4: MAPK1 | C4: =VLOOKUP(B4,Proteome!B:I,8,FALSE) -> 0.0055901391 | D4: =VLOOKUP(A4,$K$2:$L$12,2,FALSE) -> 0.9 | E4: =C4*D4 -> 0.0050311252 | F4: =SUM($E$2:$E$522) -> 0.36158134 | G4: =E4/F4 -> 0.013914228 | H4: =-G4*LOG(G4,2) -> 0.085813152 | I4: =SUM($H$2:$H$522) -> 7.7265767 | K4: Tyr | L4: 0.1
A5: CMGC | B5: MAPK12 | C5: =VLOOKUP(B5,Proteome!B:I,8,FALSE) -> 0.0055901391 | D5: =VLOOKUP(A5,$K$2:$L$12,2,FALSE) -> 0.9 | E5: =C5*D5 -> 0.0050311252 | F5: =SUM($E$2:$E$522) -> 0.36158134 | G5: =E5/F5 -> 0.013914228 | H5: =-G5*LOG(G5,2) -> 0.085813152 | I5: =SUM($H$2:$H$522) -> 7.7265767 | K5: CK1 | L5: 0.3
A6: CMGC | B6: MAPK13 | C6: =VLOOKUP(B6,Proteome!B:I,8,FALSE) -> 0.0055901391 | D6: =VLOOKUP(A6,$K$2:$L$12,2,FALSE) -> 0.9 | E6: =C6*D6 -> 0.0050311252 | F6: =SUM($E$2:$E$522) -> 0.36158134 | G6: =E6/F6 -> 0.013914228 | H6: =-G6*LOG(G6,2) -> 0.085813152 | I6: =SUM($H$2:$H$522) -> 7.7265767 | K6: Atypical | L6: 0.5
A7: CMGC | B7: MAPK14 | C7: =VLOOKUP(B7,Proteome!B:I,8,FALSE) -> 0.0055901391 | D7: =VLOOKUP(A7,$K$2:$L$12,2,FALSE) -> 0.9 | E7: =C7*D7 -> 0.0050311252 | F7: =SUM($E$2:$E$522) -> 0.36158134 | G7: =E7/F7 -> 0.013914228 | H7: =-G7*LOG(G7,2) -> 0.085813152 | I7: =SUM($H$2:$H$522) -> 7.7265767 | K7: Other | L7: 0.5
A8: CMGC | B8: MAPK3 | C8: =VLOOKUP(B8,Proteome!B:I,8,FALSE) -> 0.0055901391 | D8: =VLOOKUP(A8,$K$2:$L$12,2,FALSE) -> 0.9 | E8: =C8*D8 -> 0.0050311252 | F8: =SUM($E$2:$E$522) -> 0.36158134 | G8: =E8/F8 -> 0.013914228 | H8: =-G8*LOG(G8,2) -> 0.085813152 | I8: =SUM($H$2:$H$522) -> 7.7265767 | K8: TKL | L8: 0.3
A9: CMGC | B9: PRPF4B | C9: =VLOOKUP(B9,Proteome!B:I,8,FALSE) -> 0.0055901391 | D9: =VLOOKUP(A9,$K$2:$L$12,2,FALSE) -> 0.9 | E9: =C9*D9 -> 0.0050311252 | F9: =SUM($E$2:$E$522) -> 0.36158134 | G9: =E9/F9 -> 0.013914228 | H9: =-G9*LOG(G9,2) -> 0.085813152 | I9: =SUM($H$2:$H$522) -> 7.7265767 | K9: CMGC | L9: 0.9
A10: CMGC | B10: CDK2 | C10: =VLOOKUP(B10,Proteome!B:I,8,FALSE) -> 0.0055901391 | D10: =VLOOKUP(A10,$K$2:$L$12,2,FALSE) -> 0.9 | E10: =C10*D10 -> 0.0050311252 | F10: =SUM($E$2:$E$522) -> 0.36158134 | G10: =E10/F10 -> 0.013914228 | H10: =-G10*LOG(G10,2) -> 0.085813152 | I10: =SUM($H$2:$H$522) -> 7.7265767 | K10: STE | L10: 0.3
A11: CMGC | B11: CDK4 | C11: =VLOOKUP(B11,Proteome!B:I,8,FALSE) -> 0.0055901391 | D11: =VLOOKUP(A11,$K$2:$L$12,2,FALSE) -> 0.9 | E11: =C11*D11 -> 0.0050311252 | F11: =SUM($E$2:$E$522) -> 0.36158134 | G11: =E11/F11 -> 0.013914228 | H11: =-G11*LOG(G11,2) -> 0.085813152 | I11: =SUM($H$2:$H$522) -> 7.7265767 | K11: RGC | L11: 0.1
A12: CMGC | B12: CDK6 | C12: =VLOOKUP(B12,Proteome!B:I,8,FALSE) -> 0.0055901391 | D12: =VLOOKUP(A12,$K$2:$L$12,2,FALSE) -> 0.9 | E12: =C12*D12 -> 0.0050311252 | F12: =SUM($E$2:$E$522) -> 0.36158134 | G12: =E12/F12 -> 0.013914228 | H12: =-G12*LOG(G12,2) -> 0.085813152 | I12: =SUM($H$2:$H$522) -> 7.7265767 | K12: NEK | L12: 0.3
A13: CMGC | B13: CDK8 | C13: =VLOOKUP(B13,Proteome!B:I,8,FALSE) -> 0.0055901391 | D13: =VLOOKUP(A13,$K$2:$L$12,2,FALSE) -> 0.9 | E13: =C13*D13 -> 0.0050311252 | F13: =SUM($E$2:$E$522) -> 0.36158134 | G13: =E13/F13 -> 0.013914228 | H13: =-G13*LOG(G13,2) -> 0.085813152 | I13: =SUM($H$2:$H$522) -> 7.7265767
A14: CMGC | B14: CDK9 | C14: =VLOOKUP(B14,Proteome!B:I,8,FALSE) -> 0.0055901391 | D14: =VLOOKUP(A14,$K$2:$L$12,2,FALSE) -> 0.9 | E14: =C14*D14 -> 0.0050311252 | F14: =SUM($E$2:$E$522) -> 0.36158134 | G14: =E14/F14 -> 0.013914228 | H14: =-G14*LOG(G14,2) -> 0.085813152 | I14: =SUM($H$2:$H$522) -> 7.7265767
A15: CMGC | B15: CDKL1 | C15: =VLOOKUP(B15,Proteome!B:I,8,FALSE) -> 0.0055901391 | D15: =VLOOKUP(A15,$K$2:$L$12,2,FALSE) -> 0.9 | E15: =C15*D15 -> 0.0050311252 | F15: =SUM($E$2:$E$522) -> 0.36158134 | G15: =E15/F15 -> 0.013914228 | H15: =-G15*LOG(G15,2) -> 0.085813152 | I15: =SUM($H$2:$H$522) -> 7.7265767
A16: CMGC | B16: CLK2 | C16: =VLOOKUP(B16,Proteome!B:I,8,FALSE) -> 0.0055901391 | D16: =VLOOKUP(A16,$K$2:$L$12,2,FALSE) -> 0.9 | E16: =C16*D16 -> 0.0050311252 | F16: =SUM($E$2:$E$522) -> 0.36158134 | G16: =E16/F16 -> 0.013914228 | H16: =-G16*LOG(G16,2) -> 0.085813152 | I16: =SUM($H$2:$H$522) -> 7.7265767
A17: CMGC | B17: DYRK1A | C17: =VLOOKUP(B17,Proteome!B:I,8,FALSE) -> 0.0055901391 | D17: =VLOOKUP(A17,$K$2:$L$12,2,FALSE) -> 0.9 | E17: =C17*D17 -> 0.0050311252 | F17: =SUM($E$2:$E$522) -> 0.36158134 | G17: =E17/F17 -> 0.013914228 | H17: =-G17*LOG(G17,2) -> 0.085813152 | I17: =SUM($H$2:$H$522) -> 7.7265767
A18: CMGC | B18: HIPK1 | C18: =VLOOKUP(B18,Proteome!B:I,8,FALSE) -> 0.0029421785 | D18: =VLOOKUP(A18,$K$2:$L$12,2,FALSE) -> 0.9 | E18: =C18*D18 -> 0.0026479606 | F18: =SUM($E$2:$E$522) -> 0.36158134 | G18: =E18/F18 -> 0.0073232777 | H18: =-G18*LOG(G18,2) -> 0.051946168 | I18: =SUM($H$2:$H$522) -> 7.7265767
A19: CMGC | B19: HIPK3 | C19: =VLOOKUP(B19,Proteome!B:I,8,FALSE) -> 0.0029421785 | D19: =VLOOKUP(A19,$K$2:$L$12,2,FALSE) -> 0.9 | E19: =C19*D19 -> 0.0026479606 | F19: =SUM($E$2:$E$522) -> 0.36158134 | G19: =E19/F19 -> 0.0073232777 | H19: =-G19*LOG(G19,2) -> 0.051946168 | I19: =SUM($H$2:$H$522) -> 7.7265767
A20: CMGC | B20: MAPK6 | C20: =VLOOKUP(B20,Proteome!B:I,8,FALSE) -> 0.0055901391 | D20: =VLOOKUP(A20,$K$2:$L$12,2,FALSE) -> 0.9 | E20: =C20*D20 -> 0.0050311252 | F20: =SUM($E$2:$E$522) -> 0.36158134 | G20: =E20/F20 -> 0.013914228 | H20: =-G20*LOG(G20,2) -> 0.085813152 | I20: =SUM($H$2:$H$522) -> 7.7265767
A21: CMGC | B21: NLK | C21: =VLOOKUP(B21,Proteome!B:I,8,FALSE) -> 0.0055901391 | D21: =VLOOKUP(A21,$K$2:$L$12,2,FALSE) -> 0.9 | E21: =C21*D21 -> 0.0050311252 | F21: =SUM($E$2:$E$522) -> 0.36158134 | G21: =E21/F21 -> 0.013914228 | H21: =-G21*LOG(G21,2) -> 0.085813152 | I21: =SUM($H$2:$H$522) -> 7.7265767
A22: CMGC | B22: SRPK1 | C22: =VLOOKUP(B22,Proteome!B:I,8,FALSE) -> 0.0055901391 | D22: =VLOOKUP(A22,$K$2:$L$12,2,FALSE) -> 0.9 | E22: =C22*D22 -> 0.0050311252 | F22: =SUM($E$2:$E$522) -> 0.36158134 | G22: =E22/F22 -> 0.013914228 | H22: =-G22*LOG(G22,2) -> 0.085813152 | I22: =SUM($H$2:$H$522) -> 7.7265767
A23: CMGC | B23: CDK5 | C23: =VLOOKUP(B23,Proteome!B:I,8,FALSE) -> 0.0041190498 | D23: =VLOOKUP(A23,$K$2:$L$12,2,FALSE) -> 0.9 | E23: =C23*D23 -> 0.0037071448 | F23: =SUM($E$2:$E$522) -> 0.36158134 | G23: =E23/F23 -> 0.010252589 | H23: =-G23*LOG(G23,2) -> 0.067747753 | I23: =SUM($H$2:$H$522) -> 7.7265767
A24: CMGC | B24: CLK4 | C24: =VLOOKUP(B24,Proteome!B:I,8,FALSE) -> 0.002167921 | D24: =VLOOKUP(A24,$K$2:$L$12,2,FALSE) -> 0.9 | E24: =C24*D24 -> 0.0019511289 | F24: =SUM($E$2:$E$522) -> 0.36158134 | G24: =E24/F24 -> 0.0053960994 | H24: =-G24*LOG(G24,2) -> 0.040653497 | I24: =SUM($H$2:$H$522) -> 7.7265767
... A522: Tyr | B522: ZAP70 | C522: =VLOOKUP(B522,Proteome!B:I,8,FALSE) -> 0.00030970299 | D522: =VLOOKUP(A522,$K$2:$L$12,2,FALSE) -> 0.1 | E522: =C522*D522 -> 3.0970299e-05 | F522: =SUM($E$2:$E$522) -> 0.36158134 | G522: =E522/F522 -> 8.5652371e-05 | H522: =-G522*LOG(G522,2) -> 0.0011572618 | I522: =SUM($H$2:$H$522) -> 7.7265767

Sheet AVP Regulation (PTM & Ca-cAMP
A1: Family | B1: PFAM-Gene Name | C1: Prior Probability | D1: AVP Knowledge Base | E1: Known Effect | F1: PTM (-ve) Regulated Probability | G1: Ca2+ & cAMP (-ve) Regulation | H1: Combined Proability | I1: Partial Bayes Probability | J1: Sum | K1: Bayes Probability | L1: partial info | M1: Shannon Information | P1: Known Effect
A2: CMGC | B2: MAPK1 | C2: =VLOOKUP(B2,'Consensus Phospho site'!B:G,6,FALSE) -> 0.013914228 | D2: Mapk1 | E2: decreases total cellular activity | F2: 0.9 | G2: 0.5 | H2: =F2*G2 -> 0.45 | I2: =H2*C2 -> 0.0062614025 | J2: =SUM($I$2:$I$522) -> 0.26455 | K2: =I2/J2 -> 0.023668125 | L2: =K2*-LOG(K2,2) -> 0.12782943 | M2: =SUM($L$2:$L$522) -> 7.6126901 | P2: decrease in activity | Q2: 0.9
A3: CMGC | B3: MAPK14 | C3: =VLOOKUP(B3,'Consensus Phospho site'!B:G,6,FALSE) -> 0.013914228 | D3: Mapk14 | E3: decreases total cellular activity | F3: 0.9 | G3: 0.5 | H3: =F3*G3 -> 0.45 | I3: =H3*C3 -> 0.0062614025 | J3: =SUM($I$2:$I$522) -> 0.26455 | K3: =I3/J3 -> 0.023668125 | L3: =K3*-LOG(K3,2) -> 0.12782943 | M3: =SUM($L$2:$L$522) -> 7.6126901 | P3: Phosphorylation with unkown effect | Q3: 0.65
A4: CMGC | B4: MAPK3 | C4: =VLOOKUP(B4,'Consensus Phospho site'!B:G,6,FALSE) -> 0.013914228 | D4: Mapk3 | E4: decreases total cellular activity | F4: 0.9 | G4: 0.5 | H4: =F4*G4 -> 0.45 | I4: =H4*C4 -> 0.0062614025 | J4: =SUM($I$2:$I$522) -> 0.26455 | K4: =I4/J4 -> 0.023668125 | L4: =K4*-LOG(K4,2) -> 0.12782943 | M4: =SUM($L$2:$L$522) -> 7.6126901
A5: CMGC | B5: GSK3A | C5: =VLOOKUP(B5,'Consensus Phospho site'!B:G,6,FALSE) -> 0.010252589 | D5: Gsk3a | E5: decreases total cellular activity | F5: 0.9 | G5: 0.5 | H5: =F5*G5 -> 0.45 | I5: =H5*C5 -> 0.004613665 | J5: =SUM($I$2:$I$522) -> 0.26455 | K5: =I5/J5 -> 0.017439671 | L5: =K5*-LOG(K5,2) -> 0.10187355 | M5: =SUM($L$2:$L$522) -> 7.6126901 | P5: Phosphorylation + increase in activity | Q5: 0.2
A6: CMGC | B6: CDK2 | C6: =VLOOKUP(B6,'Consensus Phospho site'!B:G,6,FALSE) -> 0.013914228 | D6: #N/A | E6: #N/A | F6: 0.5 | G6: 0.5 | H6: =F6*G6 -> 0.25 | I6: =H6*C6 -> 0.0034785569 | J6: =SUM($I$2:$I$522) -> 0.26455 | K6: =I6/J6 -> 0.013148958 | L6: =K6*-LOG(K6,2) -> 0.082166626 | M6: =SUM($L$2:$L$522) -> 7.6126901
A7: CMGC | B7: CDK4 | C7: =VLOOKUP(B7,'Consensus Phospho site'!B:G,6,FALSE) -> 0.013914228 | D7: #N/A | E7: #N/A | F7: 0.5 | G7: 0.5 | H7: =F7*G7 -> 0.25 | I7: =H7*C7 -> 0.0034785569 | J7: =SUM($I$2:$I$522) -> 0.26455 | K7: =I7/J7 -> 0.013148958 | L7: =K7*-LOG(K7,2) -> 0.082166626 | M7: =SUM($L$2:$L$522) -> 7.6126901 | P7: unkown | Q7: 0.5
A8: CMGC | B8: CDK6 | C8: =VLOOKUP(B8,'Consensus Phospho site'!B:G,6,FALSE) -> 0.013914228 | D8: #N/A | E8: #N/A | F8: 0.5 | G8: 0.5 | H8: =F8*G8 -> 0.25 | I8: =H8*C8 -> 0.0034785569 | J8: =SUM($I$2:$I$522) -> 0.26455 | K8: =I8/J8 -> 0.013148958 | L8: =K8*-LOG(K8,2) -> 0.082166626 | M8: =SUM($L$2:$L$522) -> 7.6126901
A9: CMGC | B9: CDK8 | C9: =VLOOKUP(B9,'Consensus Phospho site'!B:G,6,FALSE) -> 0.013914228 | D9: #N/A | E9: #N/A | F9: 0.5 | G9: 0.5 | H9: =F9*G9 -> 0.25 | I9: =H9*C9 -> 0.0034785569 | J9: =SUM($I$2:$I$522) -> 0.26455 | K9: =I9/J9 -> 0.013148958 | L9: =K9*-LOG(K9,2) -> 0.082166626 | M9: =SUM($L$2:$L$522) -> 7.6126901
A10: CMGC | B10: CDK9 | C10: =VLOOKUP(B10,'Consensus Phospho site'!B:G,6,FALSE) -> 0.013914228 | D10: #N/A | E10: #N/A | F10: 0.5 | G10: 0.5 | H10: =F10*G10 -> 0.25 | I10: =H10*C10 -> 0.0034785569 | J10: =SUM($I$2:$I$522) -> 0.26455 | K10: =I10/J10 -> 0.013148958 | L10: =K10*-LOG(K10,2) -> 0.082166626 | M10: =SUM($L$2:$L$522) -> 7.6126901
A11: CMGC | B11: CDKL1 | C11: =VLOOKUP(B11,'Consensus Phospho site'!B:G,6,FALSE) -> 0.013914228 | D11: #N/A | E11: #N/A | F11: 0.5 | G11: 0.5 | H11: =F11*G11 -> 0.25 | I11: =H11*C11 -> 0.0034785569 | J11: =SUM($I$2:$I$522) -> 0.26455 | K11: =I11/J11 -> 0.013148958 | L11: =K11*-LOG(K11,2) -> 0.082166626 | M11: =SUM($L$2:$L$522) -> 7.6126901
A12: CMGC | B12: CLK1 | C12: =VLOOKUP(B12,'Consensus Phospho site'!B:G,6,FALSE) -> 0.013914228 | D12: #N/A | E12: #N/A | F12: 0.5 | G12: 0.5 | H12: =F12*G12 -> 0.25 | I12: =H12*C12 -> 0.0034785569 | J12: =SUM($I$2:$I$522) -> 0.26455 | K12: =I12/J12 -> 0.013148958 | L12: =K12*-LOG(K12,2) -> 0.082166626 | M12: =SUM($L$2:$L$522) -> 7.6126901
A13: CMGC | B13: CLK2 | C13: =VLOOKUP(B13,'Consensus Phospho site'!B:G,6,FALSE) -> 0.013914228 | D13: #N/A | E13: #N/A | F13: 0.5 | G13: 0.5 | H13: =F13*G13 -> 0.25 | I13: =H13*C13 -> 0.0034785569 | J13: =SUM($I$2:$I$522) -> 0.26455 | K13: =I13/J13 -> 0.013148958 | L13: =K13*-LOG(K13,2) -> 0.082166626 | M13: =SUM($L$2:$L$522) -> 7.6126901
A14: CMGC | B14: DYRK1A | C14: =VLOOKUP(B14,'Consensus Phospho site'!B:G,6,FALSE) -> 0.013914228 | D14: #N/A | E14: #N/A | F14: 0.5 | G14: 0.5 | H14: =F14*G14 -> 0.25 | I14: =H14*C14 -> 0.0034785569 | J14: =SUM($I$2:$I$522) -> 0.26455 | K14: =I14/J14 -> 0.013148958 | L14: =K14*-LOG(K14,2) -> 0.082166626 | M14: =SUM($L$2:$L$522) -> 7.6126901
A15: CMGC | B15: GSK3B | C15: =VLOOKUP(B15,'Consensus Phospho site'!B:G,6,FALSE) -> 0.013914228 | D15: #N/A | E15: #N/A | F15: 0.5 | G15: 0.5 | H15: =F15*G15 -> 0.25 | I15: =H15*C15 -> 0.0034785569 | J15: =SUM($I$2:$I$522) -> 0.26455 | K15: =I15/J15 -> 0.013148958 | L15: =K15*-LOG(K15,2) -> 0.082166626 | M15: =SUM($L$2:$L$522) -> 7.6126901
A16: CMGC | B16: MAPK12 | C16: =VLOOKUP(B16,'Consensus Phospho site'!B:G,6,FALSE) -> 0.013914228 | D16: #N/A | E16: #N/A | F16: 0.5 | G16: 0.5 | H16: =F16*G16 -> 0.25 | I16: =H16*C16 -> 0.0034785569 | J16: =SUM($I$2:$I$522) -> 0.26455 | K16: =I16/J16 -> 0.013148958 | L16: =K16*-LOG(K16,2) -> 0.082166626 | M16: =SUM($L$2:$L$522) -> 7.6126901
A17: CMGC | B17: MAPK13 | C17: =VLOOKUP(B17,'Consensus Phospho site'!B:G,6,FALSE) -> 0.013914228 | D17: #N/A | E17: #N/A | F17: 0.5 | G17: 0.5 | H17: =F17*G17 -> 0.25 | I17: =H17*C17 -> 0.0034785569 | J17: =SUM($I$2:$I$522) -> 0.26455 | K17: =I17/J17 -> 0.013148958 | L17: =K17*-LOG(K17,2) -> 0.082166626 | M17: =SUM($L$2:$L$522) -> 7.6126901
A18: CMGC | B18: MAPK6 | C18: =VLOOKUP(B18,'Consensus Phospho site'!B:G,6,FALSE) -> 0.013914228 | D18: #N/A | E18: #N/A | F18: 0.5 | G18: 0.5 | H18: =F18*G18 -> 0.25 | I18: =H18*C18 -> 0.0034785569 | J18: =SUM($I$2:$I$522) -> 0.26455 | K18: =I18/J18 -> 0.013148958 | L18: =K18*-LOG(K18,2) -> 0.082166626 | M18: =SUM($L$2:$L$522) -> 7.6126901
A19: CMGC | B19: NLK | C19: =VLOOKUP(B19,'Consensus Phospho site'!B:G,6,FALSE) -> 0.013914228 | D19: #N/A | E19: #N/A | F19: 0.5 | G19: 0.5 | H19: =F19*G19 -> 0.25 | I19: =H19*C19 -> 0.0034785569 | J19: =SUM($I$2:$I$522) -> 0.26455 | K19: =I19/J19 -> 0.013148958 | L19: =K19*-LOG(K19,2) -> 0.082166626 | M19: =SUM($L$2:$L$522) -> 7.6126901
... A21: CMGC | B21: SRPK1 | C21: =VLOOKUP(B21,'Consensus Phospho site'!B:G,6,FALSE) -> 0.013914228 | D21: #N/A | E21: #N/A | F21: 0.5 | G21: 0.5 | H21: =F21*G21 -> 0.25 | I21: =H21*C21 -> 0.0034785569 | J21: =SUM($I$2:$I$522) -> 0.26455 | K21: =I21/J21 -> 0.013148958 | L21: =K21*-LOG(K21,2) -> 0.082166626 | M21: =SUM($L$2:$L$522) -> 7.6126901
A22: CMGC | B22: MAPK8 | C22: =VLOOKUP(B22,'Consensus Phospho site'!B:G,6,FALSE) -> 0.010252589 | D22: Mapk8 | E22: unknown | F22: 0.65 | G22: 0.5 | H22: =F22*G22 -> 0.325 | I22: =H22*C22 -> 0.0033320914 | J22: =SUM($I$2:$I$522) -> 0.26455 | K22: =I22/J22 -> 0.012595318 | L22: =K22*-LOG(K22,2) -> 0.079488656 | M22: =SUM($L$2:$L$522) -> 7.6126901
A23: CMGC | B23: CDK5 | C23: =VLOOKUP(B23,'Consensus Phospho site'!B:G,6,FALSE) -> 0.010252589 | D23: #N/A | E23: #N/A | F23: 0.5 | G23: 0.5 | H23: =F23*G23 -> 0.25 | I23: =H23*C23 -> 0.0025631472 | J23: =SUM($I$2:$I$522) -> 0.26455 | K23: =I23/J23 -> 0.009688706 | L23: =K23*-LOG(K23,2) -> 0.064812408 | M23: =SUM($L$2:$L$522) -> 7.6126901
A24: CMGC | B24: HIPK2 | C24: =VLOOKUP(B24,'Consensus Phospho site'!B:G,6,FALSE) -> 0.010252589 | D24: #N/A | E24: #N/A | F24: 0.5 | G24: 0.5 | H24: =F24*G24 -> 0.25 | I24: =H24*C24 -> 0.0025631472 | J24: =SUM($I$2:$I$522) -> 0.26455 | K24: =I24/J24 -> 0.009688706 | L24: =K24*-LOG(K24,2) -> 0.064812408 | M24: =SUM($L$2:$L$522) -> 7.6126901
A25: Other | B25: AAK1 | C25: =VLOOKUP(B25,'Consensus Phospho site'!B:G,6,FALSE) -> 0.0077301265 | D25: Aak1 | E25: unknown | F25: 0.65 | G25: 0.5 | H25: =F25*G25 -> 0.325 | I25: =H25*C25 -> 0.0025122911 | J25: =SUM($I$2:$I$522) -> 0.26455 | K25: =I25/J25 -> 0.0094964698 | L25: =K25*-LOG(K25,2) -> 0.063801016 | M25: =SUM($L$2:$L$522) -> 7.6126901
A26: STE | B26: MAP2K1 | C26: =VLOOKUP(B26,'Consensus Phospho site'!B:G,6,FALSE) -> 0.0046380759 | D26: Map2k1 | E26: decreases total cellular activity | F26: 0.9 | G26: 0.5 | H26: =F26*G26 -> 0.45 | I26: =H26*C26 -> 0.0020871342 | J26: =SUM($I$2:$I$522) -> 0.26455 | K26: =I26/J26 -> 0.0078893749 | L26: =K26*-LOG(K26,2) -> 0.055114173 | M26: =SUM($L$2:$L$522) -> 7.6126901
A27: STE | B27: MAP2K2 | C27: =VLOOKUP(B27,'Consensus Phospho site'!B:G,6,FALSE) -> 0.0046380759 | D27: Map2k2 | E27: decreases total cellular activity | F27: 0.9 | G27: 0.5 | H27: =F27*G27 -> 0.45 | I27: =H27*C27 -> 0.0020871342 | J27: =SUM($I$2:$I$522) -> 0.26455 | K27: =I27/J27 -> 0.0078893749 | L27: =K27*-LOG(K27,2) -> 0.055114173 | M27: =SUM($L$2:$L$522) -> 7.6126901
A28: STE | B28: MAP2K3 | C28: =VLOOKUP(B28,'Consensus Phospho site'!B:G,6,FALSE) -> 0.0046380759 | D28: Map2k3 | E28: decreases total cellular activity | F28: 0.9 | G28: 0.5 | H28: =F28*G28 -> 0.45 | I28: =H28*C28 -> 0.0020871342 | J28: =SUM($I$2:$I$522) -> 0.26455 | K28: =I28/J28 -> 0.0078893749 | L28: =K28*-LOG(K28,2) -> 0.055114173 | M28: =SUM($L$2:$L$522) -> 7.6126901
A29: TKL | B29: RAF1 | C29: =VLOOKUP(B29,'Consensus Phospho site'!B:G,6,FALSE) -> 0.0046380759 | D29: Raf1 | E29: decreases total cellular activity | F29: 0.9 | G29: 0.5 | H29: =F29*G29 -> 0.45 | I29: =H29*C29 -> 0.0020871342 | J29: =SUM($I$2:$I$522) -> 0.26455 | K29: =I29/J29 -> 0.0078893749 | L29: =K29*-LOG(K29,2) -> 0.055114173 | M29: =SUM($L$2:$L$522) -> 7.6126901
A30: Other | B30: AURKA | C30: =VLOOKUP(B30,'Consensus Phospho site'!B:G,6,FALSE) -> 0.0077301265 | D30: #N/A | E30: #N/A | F30: 0.5 | G30: 0.5 | H30: =F30*G30 -> 0.25 | I30: =H30*C30 -> 0.0019325316 | J30: =SUM($I$2:$I$522) -> 0.26455 | K30: =I30/J30 -> 0.0073049767 | L30: =K30*-LOG(K30,2) -> 0.051842723 | M30: =SUM($L$2:$L$522) -> 7.6126901
A31: Other | B31: BUB1 | C31: =VLOOKUP(B31,'Consensus Phospho site'!B:G,6,FALSE) -> 0.0077301265 | D31: #N/A | E31: #N/A | F31: 0.5 | G31: 0.5 | H31: =F31*G31 -> 0.25 | I31: =H31*C31 -> 0.0019325316 | J31: =SUM($I$2:$I$522) -> 0.26455 | K31: =I31/J31 -> 0.0073049767 | L31: =K31*-LOG(K31,2) -> 0.051842723 | M31: =SUM($L$2:$L$522) -> 7.6126901
A32: Other | B32: BUB1B | C32: =VLOOKUP(B32,'Consensus Phospho site'!B:G,6,FALSE) -> 0.0077301265 | D32: #N/A | E32: #N/A | F32: 0.5 | G32: 0.5 | H32: =F32*G32 -> 0.25 | I32: =H32*C32 -> 0.0019325316 | J32: =SUM($I$2:$I$522) -> 0.26455 | K32: =I32/J32 -> 0.0073049767 | L32: =K32*-LOG(K32,2) -> 0.051842723 | M32: =SUM($L$2:$L$522) -> 7.6126901
A33: Other | B33: CDC7 | C33: =VLOOKUP(B33,'Consensus Phospho site'!B:G,6,FALSE) -> 0.0077301265 | D33: #N/A | E33: #N/A | F33: 0.5 | G33: 0.5 | H33: =F33*G33 -> 0.25 | I33: =H33*C33 -> 0.0019325316 | J33: =SUM($I$2:$I$522) -> 0.26455 | K33: =I33/J33 -> 0.0073049767 | L33: =K33*-LOG(K33,2) -> 0.051842723 | M33: =SUM($L$2:$L$522) -> 7.6126901
A34: Other | B34: CSNK2A1 | C34: =VLOOKUP(B34,'Consensus Phospho site'!B:G,6,FALSE) -> 0.0077301265 | D34: #N/A | E34: #N/A | F34: 0.5 | G34: 0.5 | H34: =F34*G34 -> 0.25 | I34: =H34*C34 -> 0.0019325316 | J34: =SUM($I$2:$I$522) -> 0.26455 | K34: =I34/J34 -> 0.0073049767 | L34: =K34*-LOG(K34,2) -> 0.051842723 | M34: =SUM($L$2:$L$522) -> 7.6126901
A35: Other | B35: CSNK2A2 | C35: =VLOOKUP(B35,'Consensus Phospho site'!B:G,6,FALSE) -> 0.0077301265 | D35: #N/A | E35: #N/A | F35: 0.5 | G35: 0.5 | H35: =F35*G35 -> 0.25 | I35: =H35*C35 -> 0.0019325316 | J35: =SUM($I$2:$I$522) -> 0.26455 | K35: =I35/J35 -> 0.0073049767 | L35: =K35*-LOG(K35,2) -> 0.051842723 | M35: =SUM($L$2:$L$522) -> 7.6126901
A36: Other | B36: GAK | C36: =VLOOKUP(B36,'Consensus Phospho site'!B:G,6,FALSE) -> 0.0077301265 | D36: #N/A | E36: #N/A | F36: 0.5 | G36: 0.5 | H36: =F36*G36 -> 0.25 | I36: =H36*C36 -> 0.0019325316 | J36: =SUM($I$2:$I$522) -> 0.26455 | K36: =I36/J36 -> 0.0073049767 | L36: =K36*-LOG(K36,2) -> 0.051842723 | M36: =SUM($L$2:$L$522) -> 7.6126901
A37: Other | B37: IKBKB | C37: =VLOOKUP(B37,'Consensus Phospho site'!B:G,6,FALSE) -> 0.0077301265 | D37: #N/A | E37: #N/A | F37: 0.5 | G37: 0.5 | H37: =F37*G37 -> 0.25 | I37: =H37*C37 -> 0.0019325316 | J37: =SUM($I$2:$I$522) -> 0.26455 | K37: =I37/J37 -> 0.0073049767 | L37: =K37*-LOG(K37,2) -> 0.051842723 | M37: =SUM($L$2:$L$522) -> 7.6126901
A38: Atypical | B38: PDK1 | C38: =VLOOKUP(B38,'Consensus Phospho site'!B:G,6,FALSE) -> 0.0077301265 | D38: #N/A | E38: #N/A | F38: 0.5 | G38: 0.5 | H38: =F38*G38 -> 0.25 | I38: =H38*C38 -> 0.0019325316 | J38: =SUM($I$2:$I$522) -> 0.26455 | K38: =I38/J38 -> 0.0073049767 | L38: =K38*-LOG(K38,2) -> 0.051842723 | M38: =SUM($L$2:$L$522) -> 7.6126901
A39: Atypical | B39: PIK3CA | C39: =VLOOKUP(B39,'Consensus Phospho site'!B:G,6,FALSE) -> 0.0077301265 | D39: #N/A | E39: #N/A | F39: 0.5 | G39: 0.5 | H39: =F39*G39 -> 0.25 | I39: =H39*C39 -> 0.0019325316 | J39: =SUM($I$2:$I$522) -> 0.26455 | K39: =I39/J39 -> 0.0073049767 | L39: =K39*-LOG(K39,2) -> 0.051842723 | M39: =SUM($L$2:$L$522) -> 7.6126901
A40: Other | B40: PKMYT1 | C40: =VLOOKUP(B40,'Consensus Phospho site'!B:G,6,FALSE) -> 0.0077301265 | D40: #N/A | E40: #N/A | F40: 0.5 | G40: 0.5 | H40: =F40*G40 -> 0.25 | I40: =H40*C40 -> 0.0019325316 | J40: =SUM($I$2:$I$522) -> 0.26455 | K40: =I40/J40 -> 0.0073049767 | L40: =K40*-LOG(K40,2) -> 0.051842723 | M40: =SUM($L$2:$L$522) -> 7.6126901
A41: Other | B41: PLK1 | C41: =VLOOKUP(B41,'Consensus Phospho site'!B:G,6,FALSE) -> 0.0077301265 | D41: #N/A | E41: #N/A | F41: 0.5 | G41: 0.5 | H41: =F41*G41 -> 0.25 | I41: =H41*C41 -> 0.0019325316 | J41: =SUM($I$2:$I$522) -> 0.26455 | K41: =I41/J41 -> 0.0073049767 | L41: =K41*-LOG(K41,2) -> 0.051842723 | M41: =SUM($L$2:$L$522) -> 7.6126901
...

Sheet AQP2 Colocalization
A1: PFAM-Gene Name | B1: Colocalization Probability | C1: Prior Bayes Probability | D1: Partial Bayes Probability | E1: SUM | F1: Bayes Probability | H1: Partial Information | J1: Shannon Info
A2: MAPK1 | B2: 0.9 | C2: =VLOOKUP(A2,'AVP Regulation (PTM & Ca-cAMP'!B:K,10,FALSE) -> 0.023668125 | D2: =C2*B2 -> 0.021301312 | E2: =SUM($D$2:$D$522) -> 0.54181328 | F2: =D2/E2 -> 0.039314858 | H2: =-F2*LOG(F2,2) -> 0.18355248 | J2: =SUM(H2:H522) -> 7.2561248
A3: MAPK3 | B3: 0.9 | C3: =VLOOKUP(A3,'AVP Regulation (PTM & Ca-cAMP'!B:K,10,FALSE) -> 0.023668125 | D3: =C3*B3 -> 0.021301312 | E3: =SUM($D$2:$D$522) -> 0.54181328 | F3: =D3/E3 -> 0.039314858 | H3: =-F3*LOG(F3,2) -> 0.18355248
A4: MAPK14 | B4: 0.8 | C4: =VLOOKUP(A4,'AVP Regulation (PTM & Ca-cAMP'!B:K,10,FALSE) -> 0.023668125 | D4: =C4*B4 -> 0.0189345 | E4: =SUM($D$2:$D$522) -> 0.54181328 | F4: =D4/E4 -> 0.03494654 | H4: =-F4*LOG(F4,2) -> 0.16909605
A5: CDK2 | B5: 0.9 | C5: =VLOOKUP(A5,'AVP Regulation (PTM & Ca-cAMP'!B:K,10,FALSE) -> 0.013148958 | D5: =C5*B5 -> 0.011834062 | E5: =SUM($D$2:$D$522) -> 0.54181328 | F5: =D5/E5 -> 0.021841588 | H5: =-F5*LOG(F5,2) -> 0.1204952
A6: CDK4 | B6: 0.9 | C6: =VLOOKUP(A6,'AVP Regulation (PTM & Ca-cAMP'!B:K,10,FALSE) -> 0.013148958 | D6: =C6*B6 -> 0.011834062 | E6: =SUM($D$2:$D$522) -> 0.54181328 | F6: =D6/E6 -> 0.021841588 | H6: =-F6*LOG(F6,2) -> 0.1204952
A7: MAPK13 | B7: 0.9 | C7: =VLOOKUP(A7,'AVP Regulation (PTM & Ca-cAMP'!B:K,10,FALSE) -> 0.013148958 | D7: =C7*B7 -> 0.011834062 | E7: =SUM($D$2:$D$522) -> 0.54181328 | F7: =D7/E7 -> 0.021841588 | H7: =-F7*LOG(F7,2) -> 0.1204952
A8: SRPK1 | B8: 0.8 | C8: =VLOOKUP(A8,'AVP Regulation (PTM & Ca-cAMP'!B:K,10,FALSE) -> 0.013148958 | D8: =C8*B8 -> 0.010519167 | E8: =SUM($D$2:$D$522) -> 0.54181328 | F8: =D8/E8 -> 0.019414745 | H8: =-F8*LOG(F8,2) -> 0.1104059
A9: NLK | B9: 0.8 | C9: =VLOOKUP(A9,'AVP Regulation (PTM & Ca-cAMP'!B:K,10,FALSE) -> 0.013148958 | D9: =C9*B9 -> 0.010519167 | E9: =SUM($D$2:$D$522) -> 0.54181328 | F9: =D9/E9 -> 0.019414745 | H9: =-F9*LOG(F9,2) -> 0.1104059
A10: GSK3B | B10: 0.8 | C10: =VLOOKUP(A10,'AVP Regulation (PTM & Ca-cAMP'!B:K,10,FALSE) -> 0.013148958 | D10: =C10*B10 -> 0.010519167 | E10: =SUM($D$2:$D$522) -> 0.54181328 | F10: =D10/E10 -> 0.019414745 | H10: =-F10*LOG(F10,2) -> 0.1104059
A11: CDK9 | B11: 0.8 | C11: =VLOOKUP(A11,'AVP Regulation (PTM & Ca-cAMP'!B:K,10,FALSE) -> 0.013148958 | D11: =C11*B11 -> 0.010519167 | E11: =SUM($D$2:$D$522) -> 0.54181328 | F11: =D11/E11 -> 0.019414745 | H11: =-F11*LOG(F11,2) -> 0.1104059
A12: CDK6 | B12: 0.8 | C12: =VLOOKUP(A12,'AVP Regulation (PTM & Ca-cAMP'!B:K,10,FALSE) -> 0.013148958 | D12: =C12*B12 -> 0.010519167 | E12: =SUM($D$2:$D$522) -> 0.54181328 | F12: =D12/E12 -> 0.019414745 | H12: =-F12*LOG(F12,2) -> 0.1104059
A13: MAPK12 | B13: 0.8 | C13: =VLOOKUP(A13,'AVP Regulation (PTM & Ca-cAMP'!B:K,10,FALSE) -> 0.013148958 | D13: =C13*B13 -> 0.010519167 | E13: =SUM($D$2:$D$522) -> 0.54181328 | F13: =D13/E13 -> 0.019414745 | H13: =-F13*LOG(F13,2) -> 0.1104059
A14: MAPK8 | B14: 0.8 | C14: =VLOOKUP(A14,'AVP Regulation (PTM & Ca-cAMP'!B:K,10,FALSE) -> 0.012595318 | D14: =C14*B14 -> 0.010076254 | E14: =SUM($D$2:$D$522) -> 0.54181328 | F14: =D14/E14 -> 0.018597282 | H14: =-F14*LOG(F14,2) -> 0.10691139
... A522: PRKACG | B522: 0.4 | C522: =VLOOKUP(A522,'AVP Regulation (PTM & Ca-cAMP'!B:K,10,FALSE) -> 1.6188314e-05 | D522: =C522*B522 -> 6.4753257e-06 | E522: =SUM($D$2:$D$522) -> 0.54181328 | F522: =D522/E522 -> 1.1951212e-05 | H522: =-F522*LOG(F522,2) -> 0.000195432
