Workbook

Sheet Readme
A1: Calculation of dot products for all basophiilic protein kinases versus all vasopressin-regulated basophilic sites.

Sheet Basophilic
A1: Gene Symbol | B1: 1K | C1: 4K | D1: 17K | E1: 200Kp | F1: 200Ks | G1: Group
A2: Prkca | B2: 0.012987013 | C2: 6967.4298 | D2: 4446.9855 | E2: 0.012987013 | F2: 0.012987013 | G2: Basophilic
A3: Prkcb | B3: 0.012987013 | C3: 1653.7578 | D3: 3819.8483 | E3: 0.012987013 | F3: 0.012987013 | G3: Basophilic
A4: Mark1 | B4: 0.011363636 | C4: 16012.193 | D4: 58300.01 | E4: 34323.565 | F4: 0.011363636 | G4: Basophilic
A5: Chek1 | B5: 0.018518519 | C5: 2899.3435 | D5: 5582.3133 | E5: 0.018518519 | F5: 4164.8256 | G5: Basophilic
A6: Cdc42bpa | B6: 0.0050761421 | C6: 4143.2435 | D6: 18116.947 | E6: 0.0050761421 | F6: 17667.969 | G6: Basophilic
A7: Mark3 | B7: 0.012345679 | C7: 19380.389 | D7: 95007.418 | E7: 92062.332 | F7: 0.012345679 | G7: Basophilic
A8: Prkcd | B8: 14264.44 | C8: 30282.521 | D8: 84226.432 | E8: 80154.747 | F8: 1947.1955 | G8: Basophilic
A9: Mark4 | B9: 0.012048193 | C9: 8249.465 | D9: 24594.366 | E9: 26036.02 | F9: 0.012048193 | G9: Basophilic
A10: Mark2 | B10: 36612.042 | C10: 64197.511 | D10: 232667.89 | E10: 315093.66 | F10: 6346.3851 | G10: Basophilic
A11: Pkn2 | B11: 0.009009009 | C11: 18373.893 | D11: 51031.646 | E11: 95277.013 | F11: 7815.0525 | G11: Basophilic
A12: Cdc42bpb | B12: 17461.127 | C12: 97610.019 | D12: 187124.86 | E12: 227180.86 | F12: 255819.85 | G12: Basophilic
A13: Adrbk2 | B13: 0.0125 | C13: 2870.3443 | D13: 4188.766 | E13: 0.0125 | F13: 33467.213 | G13: Basophilic
... A64: Rps6ka6 | B64: 0.010309278 | C64: 0.010309278 | D64: 0.010309278 | E64: 0.010309278 | F64: 26056.123 | G64: Basophilic
A67: Aqp2 | B67: 545393.03 | C67: 3354707 | D67: 2850345.6 | E67: 73387.841 | F67: 0.034482759 | G67: Substrate | H67: Note: this works with Sumproduct
A68: Bad | B68: 0.045454545 | C68: 0.045454545 | D68: 0.045454545 | E68: 0.045454545 | F68: 15090.71 | G68: Substrate
A69: Bok | B69: 0.043478261 | C69: 36758.442 | D69: 5853.3235 | E69: 0.043478261 | F69: 0.043478261 | G69: Substrate
A70: Cbx5 | B70: 2280763.1 | C70: 0.045454545 | D70: 997.76364 | E70: 0.045454545 | F70: 162589.79 | G70: Substrate
A71: Ctnnb1 | B71: 2551212.4 | C71: 635979.57 | D71: 1705318.7 | E71: 107375.34 | F71: 73076.627 | G71: Substrate
A72: Flna | B72: 111993.59 | C72: 37657.265 | D72: 98842.043 | E72: 352125.38 | F72: 2159380.2 | G72: Substrate
A73: Hist1h1d | B73: 2.0279487e+08 | C73: 1581576.6 | D73: 6070383.5 | E73: 6976332.1 | F73: 16551.097 | G73: Substrate
A74: Hist1h1e | B74: 1.3026061e+08 | C74: 446063.83 | D74: 5352226 | E74: 4674700.7 | F74: 9735.9582 | G74: Substrate
A75: Itpr3 | B75: 2830.2096 | C75: 2485.793 | D75: 1728.0687 | E75: 0.0032894737 | F75: 0.0032894737 | G75: Substrate
A76: Kif13b | B76: 14357.664 | C76: 21100.269 | D76: 56904.503 | E76: 328546.03 | F76: 660891.9 | G76: Substrate
A77: Lcmt1 | B77: 0.026315789 | C77: 0.026315789 | D77: 48289.586 | E77: 20894.753 | F77: 2294370.3 | G77: Substrate
A78: Mcm2 | B78: 3030004.4 | C78: 121485.14 | D78: 434060.89 | E78: 6427753.5 | F78: 2387169.5 | G78: Substrate
A79: Sec22b | B79: 3535448.7 | C79: 708847.19 | D79: 945241.14 | E79: 859128.26 | F79: 19556.529 | G79: Substrate
... A81: Stmn1 | B81: 173368.79 | C81: 80921.925 | D81: 326492.57 | E81: 79929.674 | F81: 4607606.7 | G81: Substrate

Sheet Dot Product
A1: Gene Symbol | B1: Aqp2 | C1: Bad | D1: Bok | E1: Cbx5 | F1: Ctnnb1 | G1: Flna | H1: Hist1h1d | I1: Hist1h1e | J1: Itpr3 | K1: Kif13b | L1: Lcmt1 | M1: Mcm2 | N1: Sec22b | O1: Sorbs2 | P1: Stmn1
A2: Prkca | B2: =SUMPRODUCT(Basophilic!$B2:$F2, Basophilic!$B$67:$F$67) -> 3.6049139e+10 | C2: =SUMPRODUCT(Basophilic!$B2:$F2, Basophilic!$B$68:$F$68) -> 714.82149 | D2: =SUMPRODUCT(Basophilic!$B2:$F2, Basophilic!$B$69:$F$69) -> 2.8214151e+08 | E2: =SUMPRODUCT(Basophilic!$B2:$F2, Basophilic!$B$70:$F$70) -> 4469088.9 | F2: =SUMPRODUCT(Basophilic!$B2:$F2, Basophilic!$B$71:$F$71) -> 1.2014706e+10 | G2: =SUMPRODUCT(Basophilic!$B2:$F2, Basophilic!$B$72:$F$72) -> 7.0195755e+08 | H2: =SUMPRODUCT(Basophilic!$B2:$F2, Basophilic!$B$73:$F$73) -> 3.8017155e+10 | I2: =SUMPRODUCT(Basophilic!$B2:$F2, Basophilic!$B$74:$F$74) -> 2.6910942e+10 | J2: =SUMPRODUCT(Basophilic!$B2:$F2, Basophilic!$B$75:$F$75) -> 25004321 | K2: =SUMPRODUCT(Basophilic!$B2:$F2, Basophilic!$B$76:$F$76) -> 4.0008118e+08 | L2: =SUMPRODUCT(Basophilic!$B2:$F2, Basophilic!$B$77:$F$77) -> 2.1477334e+08 | M2: =SUMPRODUCT(Basophilic!$B2:$F2, Basophilic!$B$78:$F$78) -> 2.7768555e+09 | N2: =SUMPRODUCT(Basophilic!$B2:$F2, Basophilic!$B$79:$F$79) -> 9.142374e+09 | O2: =SUMPRODUCT(Basophilic!$B2:$F2, Basophilic!$B$80:$F$80) -> 17715400 | P2: =SUMPRODUCT(Basophilic!$B2:$F2, Basophilic!$B$81:$F$81) -> 2.0157887e+09 | R2: Note: change each column number of sub
A3: Prkcb | B3: =SUMPRODUCT(Basophilic!$B3:$F3, Basophilic!$B$67:$F$67) -> 1.6435769e+10 | C3: =SUMPRODUCT(Basophilic!$B3:$F3, Basophilic!$B$68:$F$68) -> 444.78471 | D3: =SUMPRODUCT(Basophilic!$B3:$F3, Basophilic!$B$69:$F$69) -> 83148370 | E3: =SUMPRODUCT(Basophilic!$B3:$F3, Basophilic!$B$70:$F$70) -> 3843112.8 | F3: =SUMPRODUCT(Basophilic!$B3:$F3, Basophilic!$B$71:$F$71) -> 7.5658505e+09 | G3: =SUMPRODUCT(Basophilic!$B3:$F3, Basophilic!$B$72:$F$72) -> 4.3987168e+08 | H3: =SUMPRODUCT(Basophilic!$B3:$F3, Basophilic!$B$73:$F$73) -> 2.5806213e+10 | I3: =SUMPRODUCT(Basophilic!$B3:$F3, Basophilic!$B$74:$F$74) -> 2.1184125e+10 | J3: =SUMPRODUCT(Basophilic!$B3:$F3, Basophilic!$B$75:$F$75) -> 10711897 | K3: =SUMPRODUCT(Basophilic!$B3:$F3, Basophilic!$B$76:$F$76) -> 2.5227434e+08 | L3: =SUMPRODUCT(Basophilic!$B3:$F3, Basophilic!$B$77:$F$77) -> 1.8448901e+08 | M3: =SUMPRODUCT(Basophilic!$B3:$F3, Basophilic!$B$78:$F$78) -> 1.8591076e+09 | N3: =SUMPRODUCT(Basophilic!$B3:$F3, Basophilic!$B$79:$F$79) -> 4.7829967e+09 | O3: =SUMPRODUCT(Basophilic!$B3:$F3, Basophilic!$B$80:$F$80) -> 5231237.6 | P3: =SUMPRODUCT(Basophilic!$B3:$F3, Basophilic!$B$81:$F$81) -> 1.3810405e+09
A4: Mark1 | B4: =SUMPRODUCT(Basophilic!$B4:$F4, Basophilic!$B$67:$F$67) -> 2.2241033e+11 | C4: =SUMPRODUCT(Basophilic!$B4:$F4, Basophilic!$B$68:$F$68) -> 5109.4753 | D4: =SUMPRODUCT(Basophilic!$B4:$F4, Basophilic!$B$69:$F$69) -> 9.2983357e+08 | E4: =SUMPRODUCT(Basophilic!$B4:$F4, Basophilic!$B$70:$F$70) -> 58199684 | F4: =SUMPRODUCT(Basophilic!$B4:$F4, Basophilic!$B$71:$F$71) -> 1.1328906e+11 | G4: =SUMPRODUCT(Basophilic!$B4:$F4, Basophilic!$B$72:$F$72) -> 1.8451692e+10 | H4: =SUMPRODUCT(Basophilic!$B4:$F4, Basophilic!$B$73:$F$73) -> 6.1868283e+11 | I4: =SUMPRODUCT(Basophilic!$B4:$F4, Basophilic!$B$74:$F$74) -> 4.7963116e+11 | J4: =SUMPRODUCT(Basophilic!$B4:$F4, Basophilic!$B$75:$F$75) -> 1.4054956e+08 | K4: =SUMPRODUCT(Basophilic!$B4:$F4, Basophilic!$B$76:$F$76) -> 1.4932274e+10 | L4: =SUMPRODUCT(Basophilic!$B4:$F4, Basophilic!$B$77:$F$77) -> 3.5324923e+09 | M4: =SUMPRODUCT(Basophilic!$B4:$F4, Basophilic!$B$78:$F$78) -> 2.4787448e+11 | N4: =SUMPRODUCT(Basophilic!$B4:$F4, Basophilic!$B$79:$F$79) -> 9.5946152e+10 | O4: =SUMPRODUCT(Basophilic!$B4:$F4, Basophilic!$B$80:$F$80) -> 58564941 | P4: =SUMPRODUCT(Basophilic!$B4:$F4, Basophilic!$B$81:$F$81) -> 2.3073784e+10
A5: Chek1 | B5: =SUMPRODUCT(Basophilic!$B5:$F5, Basophilic!$B$67:$F$67) -> 2.5637982e+10 | C5: =SUMPRODUCT(Basophilic!$B5:$F5, Basophilic!$B$68:$F$68) -> 62850562 | D5: =SUMPRODUCT(Basophilic!$B5:$F5, Basophilic!$B$69:$F$69) -> 1.3925062e+08 | E5: =SUMPRODUCT(Basophilic!$B5:$F5, Basophilic!$B$70:$F$70) -> 6.8277031e+08 | F5: =SUMPRODUCT(Basophilic!$B5:$F5, Basophilic!$B$71:$F$71) -> 1.1667947e+10 | G5: =SUMPRODUCT(Basophilic!$B5:$F5, Basophilic!$B$72:$F$72) -> 9.6543994e+09 | H5: =SUMPRODUCT(Basophilic!$B5:$F5, Basophilic!$B$73:$F$73) -> 3.8545134e+10 | I5: =SUMPRODUCT(Basophilic!$B5:$F5, Basophilic!$B$74:$F$74) -> 3.1214142e+10 | J5: =SUMPRODUCT(Basophilic!$B5:$F5, Basophilic!$B$75:$F$75) -> 16853855 | K5: =SUMPRODUCT(Basophilic!$B5:$F5, Basophilic!$B$76:$F$76) -> 3.1313416e+09 | L5: =SUMPRODUCT(Basophilic!$B5:$F5, Basophilic!$B$77:$F$77) -> 9.8252205e+09 | M5: =SUMPRODUCT(Basophilic!$B5:$F5, Basophilic!$B$78:$F$78) -> 1.2717611e+10 | N5: =SUMPRODUCT(Basophilic!$B5:$F5, Basophilic!$B$79:$F$79) -> 7.4133546e+09 | O5: =SUMPRODUCT(Basophilic!$B5:$F5, Basophilic!$B$80:$F$80) -> 8757514.9 | P5: =SUMPRODUCT(Basophilic!$B5:$F5, Basophilic!$B$81:$F$81) -> 2.1247087e+10
A6: Cdc42bpa | B6: =SUMPRODUCT(Basophilic!$B6:$F6, Basophilic!$B$67:$F$67) -> 6.553893e+10 | C6: =SUMPRODUCT(Basophilic!$B6:$F6, Basophilic!$B$68:$F$68) -> 2.666232e+08 | D6: =SUMPRODUCT(Basophilic!$B6:$F6, Basophilic!$B$69:$F$69) -> 2.5834429e+08 | E6: =SUMPRODUCT(Basophilic!$B6:$F6, Basophilic!$B$70:$F$70) -> 2.8907195e+09 | F6: =SUMPRODUCT(Basophilic!$B6:$F6, Basophilic!$B$71:$F$71) -> 3.4821315e+10 | G6: =SUMPRODUCT(Basophilic!$B6:$F6, Basophilic!$B$72:$F$72) -> 4.0098604e+10 | H6: =SUMPRODUCT(Basophilic!$B6:$F6, Basophilic!$B$73:$F$73) -> 1.1682316e+11 | I6: =SUMPRODUCT(Basophilic!$B6:$F6, Basophilic!$B$74:$F$74) -> 9.8986843e+10 | J6: =SUMPRODUCT(Basophilic!$B6:$F6, Basophilic!$B$75:$F$75) -> 41606646 | K6: =SUMPRODUCT(Basophilic!$B6:$F6, Basophilic!$B$76:$F$76) -> 1.2794978e+10 | L6: =SUMPRODUCT(Basophilic!$B6:$F6, Basophilic!$B$77:$F$77) -> 4.1411723e+10 | M6: =SUMPRODUCT(Basophilic!$B6:$F6, Basophilic!$B$78:$F$78) -> 5.0543683e+10 | N6: =SUMPRODUCT(Basophilic!$B6:$F6, Basophilic!$B$79:$F$79) -> 2.0407356e+10 | O6: =SUMPRODUCT(Basophilic!$B6:$F6, Basophilic!$B$80:$F$80) -> 16279656 | P6: =SUMPRODUCT(Basophilic!$B6:$F6, Basophilic!$B$81:$F$81) -> 8.7657379e+10
A7: Mark3 | B7: =SUMPRODUCT(Basophilic!$B7:$F7, Basophilic!$B$67:$F$67) -> 3.4257576e+11 | C7: =SUMPRODUCT(Basophilic!$B7:$F7, Basophilic!$B$68:$F$68) -> 9570.4029 | D7: =SUMPRODUCT(Basophilic!$B7:$F7, Basophilic!$B$69:$F$69) -> 1.2685061e+09 | E7: =SUMPRODUCT(Basophilic!$B7:$F7, Basophilic!$B$70:$F$70) -> 94830178 | F7: =SUMPRODUCT(Basophilic!$B7:$F7, Basophilic!$B$71:$F$71) -> 1.8422872e+11 | G7: =SUMPRODUCT(Basophilic!$B7:$F7, Basophilic!$B$72:$F$72) -> 4.2538052e+10 | H7: =SUMPRODUCT(Basophilic!$B7:$F7, Basophilic!$B$73:$F$73) -> 1.2496429e+12 | I7: =SUMPRODUCT(Basophilic!$B7:$F7, Basophilic!$B$74:$F$74) -> 9.4751152e+11 | J7: =SUMPRODUCT(Basophilic!$B7:$F7, Basophilic!$B$75:$F$75) -> 2.1235532e+08 | K7: =SUMPRODUCT(Basophilic!$B7:$F7, Basophilic!$B$76:$F$76) -> 3.6062004e+10 | L7: =SUMPRODUCT(Basophilic!$B7:$F7, Basophilic!$B$77:$F$77) -> 6.5115174e+09 | M7: =SUMPRODUCT(Basophilic!$B7:$F7, Basophilic!$B$78:$F$78) -> 6.3534748e+11 | N7: =SUMPRODUCT(Basophilic!$B7:$F7, Basophilic!$B$79:$F$79) -> 1.8263605e+11 | O7: =SUMPRODUCT(Basophilic!$B7:$F7, Basophilic!$B$80:$F$80) -> 79960526 | P7: =SUMPRODUCT(Basophilic!$B7:$F7, Basophilic!$B$81:$F$81) -> 3.9946086e+10
A8: Prkcd | B8: =SUMPRODUCT(Basophilic!$B8:$F8, Basophilic!$B$67:$F$67) -> 3.5532553e+11 | C8: =SUMPRODUCT(Basophilic!$B8:$F8, Basophilic!$B$68:$F$68) -> 29394060 | D8: =SUMPRODUCT(Basophilic!$B8:$F8, Basophilic!$B$69:$F$69) -> 1.606147e+09 | E8: =SUMPRODUCT(Basophilic!$B8:$F8, Basophilic!$B$70:$F$70) -> 3.2934446e+10 | F8: =SUMPRODUCT(Basophilic!$B8:$F8, Basophilic!$B$71:$F$71) -> 2.0803253e+11 | G8: =SUMPRODUCT(Basophilic!$B8:$F8, Basophilic!$B$72:$F$72) -> 4.3492252e+10 | H8: =SUMPRODUCT(Basophilic!$B8:$F8, Basophilic!$B$73:$F$73) -> 4.0111545e+12 | I8: =SUMPRODUCT(Basophilic!$B8:$F8, Basophilic!$B$74:$F$74) -> 2.6971199e+12 | J8: =SUMPRODUCT(Basophilic!$B8:$F8, Basophilic!$B$75:$F$75) -> 2.6119676e+08 | K8: =SUMPRODUCT(Basophilic!$B8:$F8, Basophilic!$B$76:$F$76) -> 3.3258046e+10 | L8: =SUMPRODUCT(Basophilic!$B8:$F8, Basophilic!$B$77:$F$77) -> 1.0209662e+10 | M8: =SUMPRODUCT(Basophilic!$B8:$F8, Basophilic!$B$78:$F$78) -> 6.0332283e+11 | N8: =SUMPRODUCT(Basophilic!$B8:$F8, Basophilic!$B$79:$F$79) -> 2.2041245e+11 | O8: =SUMPRODUCT(Basophilic!$B8:$F8, Basophilic!$B$80:$F$80) -> 1.0109378e+08 | P8: =SUMPRODUCT(Basophilic!$B8:$F8, Basophilic!$B$81:$F$81) -> 4.7801487e+10
A9: Mark4 | B9: =SUMPRODUCT(Basophilic!$B9:$F9, Basophilic!$B$67:$F$67) -> 9.9687714e+10 | C9: =SUMPRODUCT(Basophilic!$B9:$F9, Basophilic!$B$68:$F$68) -> 2858.1732 | D9: =SUMPRODUCT(Basophilic!$B9:$F9, Basophilic!$B$69:$F$69) -> 4.4719739e+08 | E9: =SUMPRODUCT(Basophilic!$B9:$F9, Basophilic!$B$70:$F$70) -> 24570361 | F9: =SUMPRODUCT(Basophilic!$B9:$F9, Basophilic!$B$71:$F$71) -> 4.9983382e+10 | G9: =SUMPRODUCT(Basophilic!$B9:$F9, Basophilic!$B$72:$F$72) -> 1.190958e+10 | H9: =SUMPRODUCT(Basophilic!$B9:$F9, Basophilic!$B$73:$F$73) -> 3.4398276e+11 | I9: =SUMPRODUCT(Basophilic!$B9:$F9, Basophilic!$B$74:$F$74) -> 2.5702656e+11 | J9: =SUMPRODUCT(Basophilic!$B9:$F9, Basophilic!$B$75:$F$75) -> 63007336 | K9: =SUMPRODUCT(Basophilic!$B9:$F9, Basophilic!$B$76:$F$76) -> 1.0127635e+10 | L9: =SUMPRODUCT(Basophilic!$B9:$F9, Basophilic!$B$77:$F$77) -> 1.7316958e+09 | M9: =SUMPRODUCT(Basophilic!$B9:$F9, Basophilic!$B$78:$F$78) -> 1.7903082e+11 | N9: =SUMPRODUCT(Basophilic!$B9:$F9, Basophilic!$B$79:$F$79) -> 5.146354e+10 | O9: =SUMPRODUCT(Basophilic!$B9:$F9, Basophilic!$B$80:$F$80) -> 28152155 | P9: =SUMPRODUCT(Basophilic!$B9:$F9, Basophilic!$B$81:$F$81) -> 1.0778549e+10
A10: Mark2 | B10: =SUMPRODUCT(Basophilic!$B10:$F10, Basophilic!$B$67:$F$67) -> 9.2163973e+11 | C10: =SUMPRODUCT(Basophilic!$B10:$F10, Basophilic!$B$68:$F$68) -> 95800939 | D10: =SUMPRODUCT(Basophilic!$B10:$F10, Basophilic!$B$69:$F$69) -> 3.7216965e+09 | E10: =SUMPRODUCT(Basophilic!$B10:$F10, Basophilic!$B$70:$F$70) -> 8.4767417e+10 | F10: =SUMPRODUCT(Basophilic!$B10:$F10, Basophilic!$B$71:$F$71) -> 5.6530337e+11 | G10: =SUMPRODUCT(Basophilic!$B10:$F10, Basophilic!$B$72:$F$72) -> 1.5417192e+11 | H10: =SUMPRODUCT(Basophilic!$B10:$F10, Basophilic!$B$73:$F$73) -> 1.1136954e+13 | I10: =SUMPRODUCT(Basophilic!$B10:$F10, Basophilic!$B$74:$F$74) -> 7.5160646e+12 | J10: =SUMPRODUCT(Basophilic!$B10:$F10, Basophilic!$B$75:$F$75) -> 6.6526863e+08 | K10: =SUMPRODUCT(Basophilic!$B10:$F10, Basophilic!$B$76:$F$76) -> 1.2283715e+11 | L10: =SUMPRODUCT(Basophilic!$B10:$F10, Basophilic!$B$77:$F$77) -> 3.2380201e+10 | M10: =SUMPRODUCT(Basophilic!$B10:$F10, Basophilic!$B$78:$F$78) -> 2.26022e+12 | N10: =SUMPRODUCT(Basophilic!$B10:$F10, Basophilic!$B$79:$F$79) -> 6.6570347e+11 | O10: =SUMPRODUCT(Basophilic!$B10:$F10, Basophilic!$B$80:$F$80) -> 2.3440677e+08 | P10: =SUMPRODUCT(Basophilic!$B10:$F10, Basophilic!$B$81:$F$81) -> 1.4193369e+11
A11: Pkn2 | B11: =SUMPRODUCT(Basophilic!$B11:$F11, Basophilic!$B$67:$F$67) -> 2.1408903e+11 | C11: =SUMPRODUCT(Basophilic!$B11:$F11, Basophilic!$B$68:$F$68) -> 1.1794218e+08 | D11: =SUMPRODUCT(Basophilic!$B11:$F11, Basophilic!$B$69:$F$69) -> 9.7410492e+08 | E11: =SUMPRODUCT(Basophilic!$B11:$F11, Basophilic!$B$70:$F$70) -> 1.321591e+09 | F11: =SUMPRODUCT(Basophilic!$B11:$F11, Basophilic!$B$71:$F$71) -> 1.0951216e+11 | G11: =SUMPRODUCT(Basophilic!$B11:$F11, Basophilic!$B$72:$F$72) -> 5.6161108e+10 | H11: =SUMPRODUCT(Basophilic!$B11:$F11, Basophilic!$B$73:$F$73) -> 1.0036566e+12 | I11: =SUMPRODUCT(Basophilic!$B11:$F11, Basophilic!$B$74:$F$74) -> 7.2679761e+11 | J11: =SUMPRODUCT(Basophilic!$B11:$F11, Basophilic!$B$75:$F$75) -> 1.3386025e+08 | K11: =SUMPRODUCT(Basophilic!$B11:$F11, Basophilic!$B$76:$F$76) -> 3.9759414e+10 | L11: =SUMPRODUCT(Basophilic!$B11:$F11, Basophilic!$B$77:$F$77) -> 2.2385712e+10 | M11: =SUMPRODUCT(Basophilic!$B11:$F11, Basophilic!$B$78:$F$78) -> 6.5545603e+11 | N11: =SUMPRODUCT(Basophilic!$B11:$F11, Basophilic!$B$79:$F$79) -> 1.4326954e+11 | O11: =SUMPRODUCT(Basophilic!$B11:$F11, Basophilic!$B$80:$F$80) -> 61311913 | P11: =SUMPRODUCT(Basophilic!$B11:$F11, Basophilic!$B$81:$F$81) -> 6.1772454e+10
A12: Cdc42bpb | B12: =SUMPRODUCT(Basophilic!$B12:$F12, Basophilic!$B$67:$F$67) -> 8.8701904e+11 | C12: =SUMPRODUCT(Basophilic!$B12:$F12, Basophilic!$B$68:$F$68) -> 3.8605273e+09 | D12: =SUMPRODUCT(Basophilic!$B12:$F12, Basophilic!$B$69:$F$69) -> 4.6833163e+09 | E12: =SUMPRODUCT(Basophilic!$B12:$F12, Basophilic!$B$70:$F$70) -> 8.1605111e+10 | F12: =SUMPRODUCT(Basophilic!$B12:$F12, Basophilic!$B$71:$F$71) -> 4.6882063e+11 | G12: =SUMPRODUCT(Basophilic!$B12:$F12, Basophilic!$B$72:$F$72) -> 6.5653554e+11 | H12: =SUMPRODUCT(Basophilic!$B12:$F12, Basophilic!$B$73:$F$73) -> 6.4204476e+12 | I12: =SUMPRODUCT(Basophilic!$B12:$F12, Basophilic!$B$74:$F$74) -> 4.3840651e+12 | J12: =SUMPRODUCT(Basophilic!$B12:$F12, Basophilic!$B$75:$F$75) -> 6.1542316e+08 | K12: =SUMPRODUCT(Basophilic!$B12:$F12, Basophilic!$B$76:$F$76) -> 2.5666718e+11 | L12: =SUMPRODUCT(Basophilic!$B12:$F12, Basophilic!$B$77:$F$77) -> 6.0072855e+11 | M12: =SUMPRODUCT(Basophilic!$B12:$F12, Basophilic!$B$78:$F$78) -> 2.2169369e+12 | N12: =SUMPRODUCT(Basophilic!$B12:$F12, Basophilic!$B$79:$F$79) -> 5.0798207e+11 | O12: =SUMPRODUCT(Basophilic!$B12:$F12, Basophilic!$B$80:$F$80) -> 2.9453436e+08 | P12: =SUMPRODUCT(Basophilic!$B12:$F12, Basophilic!$B$81:$F$81) -> 1.2688966e+12
A13: Adrbk2 | B13: =SUMPRODUCT(Basophilic!$B13:$F13, Basophilic!$B$67:$F$67) -> 2.1568603e+10 | C13: =SUMPRODUCT(Basophilic!$B13:$F13, Basophilic!$B$68:$F$68) -> 5.0504433e+08 | D13: =SUMPRODUCT(Basophilic!$B13:$F13, Basophilic!$B$69:$F$69) -> 1.3002904e+08 | E13: =SUMPRODUCT(Basophilic!$B13:$F13, Basophilic!$B$70:$F$70) -> 5.445635e+09 | F13: =SUMPRODUCT(Basophilic!$B13:$F13, Basophilic!$B$71:$F$71) -> 1.1414366e+10 | G13: =SUMPRODUCT(Basophilic!$B13:$F13, Basophilic!$B$72:$F$72) -> 7.2790559e+10 | H13: =SUMPRODUCT(Basophilic!$B13:$F13, Basophilic!$B$73:$F$73) -> 3.0523627e+10 | I13: =SUMPRODUCT(Basophilic!$B13:$F13, Basophilic!$B$74:$F$74) -> 2.4027101e+10 | J13: =SUMPRODUCT(Basophilic!$B13:$F13, Basophilic!$B$75:$F$75) -> 14373702 | K13: =SUMPRODUCT(Basophilic!$B13:$F13, Basophilic!$B$76:$F$76) -> 2.2417139e+10 | L13: =SUMPRODUCT(Basophilic!$B13:$F13, Basophilic!$B$77:$F$77) -> 7.6988454e+10 | M13: =SUMPRODUCT(Basophilic!$B13:$F13, Basophilic!$B$78:$F$78) -> 8.2058909e+10 | N13: =SUMPRODUCT(Basophilic!$B13:$F13, Basophilic!$B$79:$F$79) -> 6.6485869e+09 | O13: =SUMPRODUCT(Basophilic!$B13:$F13, Basophilic!$B$80:$F$80) -> 8173451.5 | P13: =SUMPRODUCT(Basophilic!$B13:$F13, Basophilic!$B$81:$F$81) -> 1.5580363e+11
A14: Camk2d | B14: =SUMPRODUCT(Basophilic!$B14:$F14, Basophilic!$B$67:$F$67) -> 1.693454e+12 | C14: =SUMPRODUCT(Basophilic!$B14:$F14, Basophilic!$B$68:$F$68) -> 5.9858142e+09 | D14: =SUMPRODUCT(Basophilic!$B14:$F14, Basophilic!$B$69:$F$69) -> 8.5357758e+09 | E14: =SUMPRODUCT(Basophilic!$B14:$F14, Basophilic!$B$70:$F$70) -> 5.4724489e+11 | F14: =SUMPRODUCT(Basophilic!$B14:$F14, Basophilic!$B$71:$F$71) -> 1.3669388e+12 | G14: =SUMPRODUCT(Basophilic!$B14:$F14, Basophilic!$B$72:$F$72) -> 1.5211115e+12 | H14: =SUMPRODUCT(Basophilic!$B14:$F14, Basophilic!$B$73:$F$73) -> 5.6952833e+13 | I14: =SUMPRODUCT(Basophilic!$B14:$F14, Basophilic!$B$74:$F$74) -> 3.7230974e+13 | J14: =SUMPRODUCT(Basophilic!$B14:$F14, Basophilic!$B$75:$F$75) -> 1.5630064e+09 | K14: =SUMPRODUCT(Basophilic!$B14:$F14, Basophilic!$B$76:$F$76) -> 8.502965e+11 | L14: =SUMPRODUCT(Basophilic!$B14:$F14, Basophilic!$B$77:$F$77) -> 9.5999978e+11 | M14: =SUMPRODUCT(Basophilic!$B14:$F14, Basophilic!$B$78:$F$78) -> 1.2783684e+13 | N14: =SUMPRODUCT(Basophilic!$B14:$F14, Basophilic!$B$79:$F$79) -> 2.6386317e+12 | O14: =SUMPRODUCT(Basophilic!$B14:$F14, Basophilic!$B$80:$F$80) -> 5.3661281e+08 | P14: =SUMPRODUCT(Basophilic!$B14:$F14, Basophilic!$B$81:$F$81) -> 2.111555e+12
... A64: Rps6ka6 | B64: =SUMPRODUCT(Basophilic!$B64:$F64, Basophilic!$B$67:$F$67) -> 71247.285 | C64: =SUMPRODUCT(Basophilic!$B64:$F64, Basophilic!$B$68:$F$68) -> 3.932054e+08 | D64: =SUMPRODUCT(Basophilic!$B64:$F64, Basophilic!$B$69:$F$69) -> 1572.1724 | E64: =SUMPRODUCT(Basophilic!$B64:$F64, Basophilic!$B$70:$F$70) -> 4.2364831e+09 | F64: =SUMPRODUCT(Basophilic!$B64:$F64, Basophilic!$B$71:$F$71) -> 1.9041451e+09 | G64: =SUMPRODUCT(Basophilic!$B64:$F64, Basophilic!$B$72:$F$72) -> 5.6265084e+10 | H64: =SUMPRODUCT(Basophilic!$B64:$F64, Basophilic!$B$73:$F$73) -> 4.334989e+08 | I64: =SUMPRODUCT(Basophilic!$B64:$F64, Basophilic!$B$74:$F$74) -> 2.5513219e+08 | J64: =SUMPRODUCT(Basophilic!$B64:$F64, Basophilic!$B$75:$F$75) -> 158.33026 | K64: =SUMPRODUCT(Basophilic!$B64:$F64, Basophilic!$B$76:$F$76) -> 1.7220285e+10 | L64: =SUMPRODUCT(Basophilic!$B64:$F64, Basophilic!$B$77:$F$77) -> 5.9782397e+10 | M64: =SUMPRODUCT(Basophilic!$B64:$F64, Basophilic!$B$78:$F$78) -> 6.2200484e+10 | N64: =SUMPRODUCT(Basophilic!$B64:$F64, Basophilic!$B$79:$F$79) -> 5.0962969e+08 | O64: =SUMPRODUCT(Basophilic!$B64:$F64, Basophilic!$B$80:$F$80) -> 222.04592 | P64: =SUMPRODUCT(Basophilic!$B64:$F64, Basophilic!$B$81:$F$81) -> 1.2005637e+11

Sheet Basophilic Dot Product
A1: Gene Symbol | B1: Aqp2 | C1: Bad | D1: Bok | E1: Cbx5 | F1: Ctnnb1 | G1: Flna | H1: Hist1h1d | I1: Hist1h1e | J1: Itpr3 | K1: Kif13b | L1: Lcmt1 | M1: Mcm2 | N1: Sec22b | O1: Sorbs2 | P1: Stmn1
A2: Camk2d | B2: ='Dot Product'!B14/1000000 -> 1693454 | C2: ='Dot Product'!C14/1000000 -> 5985.8142 | D2: ='Dot Product'!D14/1000000 -> 8535.7758 | E2: ='Dot Product'!E14/1000000 -> 547244.89 | F2: ='Dot Product'!F14/1000000 -> 1366938.8 | G2: ='Dot Product'!G14/1000000 -> 1521111.5 | H2: ='Dot Product'!H14/1000000 -> 56952833 | I2: ='Dot Product'!I14/1000000 -> 37230974 | ... P2: ='Dot Product'!P14/1000000 -> 2111555
A3: Prkaa1 | B3: ='Dot Product'!B37/1000000 -> 1327024.6 | C3: ='Dot Product'!C37/1000000 -> 3823.2895 | D3: ='Dot Product'!D37/1000000 -> 2146.4638 | E3: ='Dot Product'!E37/1000000 -> 2820459.2 | F3: ='Dot Product'!F37/1000000 -> 3540896.6 | G3: ='Dot Product'!G37/1000000 -> 1034656.6 | H3: ='Dot Product'!H37/1000000 -> 2.5479611e+08 | I3: ='Dot Product'!I37/1000000 -> 1.6407675e+08 | ... P3: ='Dot Product'!P37/1000000 -> 1512662.7
A4: Mark2 | B4: ='Dot Product'!B10/1000000 -> 921639.73 | C4: ='Dot Product'!C10/1000000 -> 95.800939 | D4: ='Dot Product'!D10/1000000 -> 3721.6965 | E4: ='Dot Product'!E10/1000000 -> 84767.417 | F4: ='Dot Product'!F10/1000000 -> 565303.37 | G4: ='Dot Product'!G10/1000000 -> 154171.92 | H4: ='Dot Product'!H10/1000000 -> 11136954 | I4: ='Dot Product'!I10/1000000 -> 7516064.6 | ... P4: ='Dot Product'!P10/1000000 -> 141933.69
A5: Cdc42bpb | B5: ='Dot Product'!B12/1000000 -> 887019.04 | C5: ='Dot Product'!C12/1000000 -> 3860.5273 | D5: ='Dot Product'!D12/1000000 -> 4683.3163 | E5: ='Dot Product'!E12/1000000 -> 81605.111 | F5: ='Dot Product'!F12/1000000 -> 468820.63 | G5: ='Dot Product'!G12/1000000 -> 656535.54 | H5: ='Dot Product'!H12/1000000 -> 6420447.6 | I5: ='Dot Product'!I12/1000000 -> 4384065.1 | ... P5: ='Dot Product'!P12/1000000 -> 1268896.6
A6: Camk2a | B6: ='Dot Product'!B16/1000000 -> 840139.95 | C6: ='Dot Product'!C16/1000000 -> 3878.7939 | D6: ='Dot Product'!D16/1000000 -> 4507.1514 | E6: ='Dot Product'!E16/1000000 -> 234447.24 | F6: ='Dot Product'!F16/1000000 -> 630038.56 | G6: ='Dot Product'!G16/1000000 -> 910701.52 | H6: ='Dot Product'!H16/1000000 -> 24624081 | I6: ='Dot Product'!I16/1000000 -> 16136943 | ... P6: ='Dot Product'!P16/1000000 -> 1326066.9
A7: Camk2g | B7: ='Dot Product'!B17/1000000 -> 807068.95 | C7: ='Dot Product'!C17/1000000 -> 3740.2671 | D7: ='Dot Product'!D17/1000000 -> 4407.5589 | E7: ='Dot Product'!E17/1000000 -> 226069.17 | F7: ='Dot Product'!F17/1000000 -> 604778.76 | G7: ='Dot Product'!G17/1000000 -> 891366.57 | H7: ='Dot Product'!H17/1000000 -> 23987613 | I7: ='Dot Product'!I17/1000000 -> 15715541 | ... P7: ='Dot Product'!P17/1000000 -> 1280369.9
A8: Camk2b | B8: ='Dot Product'!B15/1000000 -> 789571.19 | C8: ='Dot Product'!C15/1000000 -> 3550.0828 | D8: ='Dot Product'!D15/1000000 -> 4237.3038 | E8: ='Dot Product'!E15/1000000 -> 214583.31 | F8: ='Dot Product'!F15/1000000 -> 585786.06 | G8: ='Dot Product'!G15/1000000 -> 834055.08 | H8: ='Dot Product'!H15/1000000 -> 22568239 | I8: ='Dot Product'!I15/1000000 -> 14794474 | ... P8: ='Dot Product'!P15/1000000 -> 1215343
A9: Prkaca | B9: ='Dot Product'!B50/1000000 -> 614768.95 | C9: ='Dot Product'!C50/1000000 -> 20727.089 | D9: ='Dot Product'!D50/1000000 -> 1134.6254 | E9: ='Dot Product'!E50/1000000 -> 1179504.8 | F9: ='Dot Product'!F50/1000000 -> 1468788.3 | G9: ='Dot Product'!G50/1000000 -> 3541465.7 | H9: ='Dot Product'!H50/1000000 -> 95833928 | I9: ='Dot Product'!I50/1000000 -> 61940142 | ... P9: ='Dot Product'!P50/1000000 -> 6545415.8
A10: Prkci | B10: ='Dot Product'!B21/1000000 -> 542894.47 | C10: ='Dot Product'!C21/1000000 -> 347.05908 | D10: ='Dot Product'!D21/1000000 -> 2021.3154 | E10: ='Dot Product'!E21/1000000 -> 95944.193 | F10: ='Dot Product'!F21/1000000 -> 441871.4 | G10: ='Dot Product'!G21/1000000 -> 497167.46 | H10: ='Dot Product'!H21/1000000 -> 17435562 | I10: ='Dot Product'!I21/1000000 -> 11569329 | ... P10: ='Dot Product'!P21/1000000 -> 248625.2
A11: Mylk4 | B11: ='Dot Product'!B43/1000000 -> 391888.92 | C11: ='Dot Product'!C43/1000000 -> 14659.141 | D11: ='Dot Product'!D43/1000000 -> 2089.5275 | E11: ='Dot Product'!E43/1000000 -> 158020.2 | F11: ='Dot Product'!F43/1000000 -> 257869.52 | G11: ='Dot Product'!G43/1000000 -> 2178181.5 | H11: ='Dot Product'!H43/1000000 -> 1979842.7 | I11: ='Dot Product'!I43/1000000 -> 1401703.1 | ... P11: ='Dot Product'!P43/1000000 -> 4521776.1
A12: Prkcd | B12: ='Dot Product'!B8/1000000 -> 355325.53 | C12: ='Dot Product'!C8/1000000 -> 29.39406 | D12: ='Dot Product'!D8/1000000 -> 1606.147 | E12: ='Dot Product'!E8/1000000 -> 32934.446 | F12: ='Dot Product'!F8/1000000 -> 208032.53 | G12: ='Dot Product'!G8/1000000 -> 43492.252 | H12: ='Dot Product'!H8/1000000 -> 4011154.5 | I12: ='Dot Product'!I8/1000000 -> 2697119.9 | ... P12: ='Dot Product'!P8/1000000 -> 47801.487
A13: Mark3 | B13: ='Dot Product'!B7/1000000 -> 342575.76 | C13: ='Dot Product'!C7/1000000 -> 0.0095704029 | D13: ='Dot Product'!D7/1000000 -> 1268.5061 | E13: ='Dot Product'!E7/1000000 -> 94.830178 | F13: ='Dot Product'!F7/1000000 -> 184228.72 | G13: ='Dot Product'!G7/1000000 -> 42538.052 | H13: ='Dot Product'!H7/1000000 -> 1249642.9 | I13: ='Dot Product'!I7/1000000 -> 947511.52 | ... P13: ='Dot Product'!P7/1000000 -> 39946.086
A14: Cask | B14: ='Dot Product'!B22/1000000 -> 315589.73 | C14: ='Dot Product'!C22/1000000 -> 0.0051138368 | D14: ='Dot Product'!D22/1000000 -> 896.26762 | E14: ='Dot Product'!E22/1000000 -> 100.73899 | F14: ='Dot Product'!F22/1000000 -> 177420.01 | G14: ='Dot Product'!G22/1000000 -> 10290.08 | H14: ='Dot Product'!H22/1000000 -> 625890.51 | I14: ='Dot Product'!I22/1000000 -> 543963.54 | ... P14: ='Dot Product'!P22/1000000 -> 33628.729
A15: Prkacb | B15: ='Dot Product'!B40/1000000 -> 283143.24 | C15: ='Dot Product'!C40/1000000 -> 12158.391 | D15: ='Dot Product'!D40/1000000 -> 396.19281 | E15: ='Dot Product'!E40/1000000 -> 283079.58 | F15: ='Dot Product'!F40/1000000 -> 428584.73 | G15: ='Dot Product'!G40/1000000 -> 2045876.9 | H15: ='Dot Product'!H40/1000000 -> 19712954 | I15: ='Dot Product'!I40/1000000 -> 12915783 | ... P15: ='Dot Product'!P40/1000000 -> 3811310.8
A16: Mylk2 | B16: ='Dot Product'!B41/1000000 -> 261259.28 | C16: ='Dot Product'!C41/1000000 -> 9772.761 | D16: ='Dot Product'!D41/1000000 -> 1393.0183 | E16: ='Dot Product'!E41/1000000 -> 105346.8 | F16: ='Dot Product'!F41/1000000 -> 171913.02 | G16: ='Dot Product'!G41/1000000 -> 1452121 | H16: ='Dot Product'!H41/1000000 -> 1319895.1 | I16: ='Dot Product'!I41/1000000 -> 934468.72 | ... P16: ='Dot Product'!P41/1000000 -> 3014517.4
A17: Mark1 | B17: ='Dot Product'!B4/1000000 -> 222410.33 | C17: ='Dot Product'!C4/1000000 -> 0.0051094753 | D17: ='Dot Product'!D4/1000000 -> 929.83357 | E17: ='Dot Product'!E4/1000000 -> 58.199684 | F17: ='Dot Product'!F4/1000000 -> 113289.06 | G17: ='Dot Product'!G4/1000000 -> 18451.692 | H17: ='Dot Product'!H4/1000000 -> 618682.83 | I17: ='Dot Product'!I4/1000000 -> 479631.16 | ... P17: ='Dot Product'!P4/1000000 -> 23073.784
A18: Pkn2 | B18: ='Dot Product'!B11/1000000 -> 214089.03 | C18: ='Dot Product'!C11/1000000 -> 117.94218 | D18: ='Dot Product'!D11/1000000 -> 974.10492 | E18: ='Dot Product'!E11/1000000 -> 1321.591 | F18: ='Dot Product'!F11/1000000 -> 109512.16 | G18: ='Dot Product'!G11/1000000 -> 56161.108 | H18: ='Dot Product'!H11/1000000 -> 1003656.6 | I18: ='Dot Product'!I11/1000000 -> 726797.61 | ... P18: ='Dot Product'!P11/1000000 -> 61772.454
A19: Mylk3 | B19: ='Dot Product'!B42/1000000 -> 200501.31 | C19: ='Dot Product'!C42/1000000 -> 7500.0259 | D19: ='Dot Product'!D42/1000000 -> 1069.0606 | E19: ='Dot Product'!E42/1000000 -> 80847.545 | F19: ='Dot Product'!F42/1000000 -> 131933.24 | G19: ='Dot Product'!G42/1000000 -> 1114418.5 | H19: ='Dot Product'!H42/1000000 -> 1012942.8 | I19: ='Dot Product'!I42/1000000 -> 717150.41 | ... P19: ='Dot Product'!P42/1000000 -> 2313466.9
A20: Mylk | B20: ='Dot Product'!B49/1000000 -> 172091.49 | C20: ='Dot Product'!C49/1000000 -> 9251.4619 | D20: ='Dot Product'!D49/1000000 -> 660.35503 | E20: ='Dot Product'!E49/1000000 -> 287488.78 | F20: ='Dot Product'!F49/1000000 -> 314988.82 | G20: ='Dot Product'!G49/1000000 -> 1351001.6 | H20: ='Dot Product'!H49/1000000 -> 17187597 | I20: ='Dot Product'!I49/1000000 -> 11079929 | ... P20: ='Dot Product'!P49/1000000 -> 2852437.9
A21: Rps6ka3 | B21: ='Dot Product'!B48/1000000 -> 141657.45 | C21: ='Dot Product'!C48/1000000 -> 7266.8634 | D21: ='Dot Product'!D48/1000000 -> 664.8333 | E21: ='Dot Product'!E48/1000000 -> 78327.805 | F21: ='Dot Product'!F48/1000000 -> 105362.21 | G21: ='Dot Product'!G48/1000000 -> 1059725.3 | H21: ='Dot Product'!H48/1000000 -> 550434.23 | I21: ='Dot Product'!I48/1000000 -> 403413.84 | ... P21: ='Dot Product'!P48/1000000 -> 2234398.6
A22: Rock2 | B22: ='Dot Product'!B52/1000000 -> 115974.19 | C22: ='Dot Product'!C52/1000000 -> 9469.5831 | D22: ='Dot Product'!D52/1000000 -> 224.28776 | E22: ='Dot Product'!E52/1000000 -> 102061.05 | F22: ='Dot Product'!F52/1000000 -> 128118.22 | G22: ='Dot Product'!G52/1000000 -> 1434656.4 | H22: ='Dot Product'!H52/1000000 -> 1729789.7 | I22: ='Dot Product'!I52/1000000 -> 1202025.6 | ... P22: ='Dot Product'!P52/1000000 -> 2919891.7
A23: Prkaa2 | B23: ='Dot Product'!B35/1000000 -> 109086.97 | C23: ='Dot Product'!C35/1000000 -> 3599.8268 | D23: ='Dot Product'!D35/1000000 -> 231.45584 | E23: ='Dot Product'!E35/1000000 -> 38820.981 | F23: ='Dot Product'!F35/1000000 -> 85984.825 | G23: ='Dot Product'!G35/1000000 -> 541278.99 | H23: ='Dot Product'!H35/1000000 -> 670692.57 | I23: ='Dot Product'!I35/1000000 -> 494918.49 | ... P23: ='Dot Product'!P35/1000000 -> 1116035.2
A24: Rps6ka1 | B24: ='Dot Product'!B46/1000000 -> 103457.12 | C24: ='Dot Product'!C46/1000000 -> 4118.2427 | D24: ='Dot Product'!D46/1000000 -> 841.84993 | E24: ='Dot Product'!E46/1000000 -> 44379.038 | F24: ='Dot Product'!F46/1000000 -> 58364.402 | G24: ='Dot Product'!G46/1000000 -> 624660.41 | H24: ='Dot Product'!H46/1000000 -> 758042.21 | I24: ='Dot Product'!I46/1000000 -> 505221.85 | ... P24: ='Dot Product'!P46/1000000 -> 1269571.8
A25: Mark4 | B25: ='Dot Product'!B9/1000000 -> 99687.714 | C25: ='Dot Product'!C9/1000000 -> 0.0028581732 | D25: ='Dot Product'!D9/1000000 -> 447.19739 | E25: ='Dot Product'!E9/1000000 -> 24.570361 | F25: ='Dot Product'!F9/1000000 -> 49983.382 | G25: ='Dot Product'!G9/1000000 -> 11909.58 | H25: ='Dot Product'!H9/1000000 -> 343982.76 | I25: ='Dot Product'!I9/1000000 -> 257026.56 | ... P25: ='Dot Product'!P9/1000000 -> 10778.549
A26: Akt1 | B26: ='Dot Product'!B18/1000000 -> 94134.505 | C26: ='Dot Product'!C18/1000000 -> 3636.3235 | D26: ='Dot Product'!D18/1000000 -> 807.20603 | E26: ='Dot Product'!E18/1000000 -> 39182.535 | F26: ='Dot Product'!F18/1000000 -> 53965.738 | G26: ='Dot Product'!G18/1000000 -> 572714.18 | H26: ='Dot Product'!H18/1000000 -> 1076970.7 | I26: ='Dot Product'!I18/1000000 -> 713704.75 | ... P26: ='Dot Product'!P18/1000000 -> 1124984.5
A27: Prkd2 | B27: ='Dot Product'!B29/1000000 -> 78577.805 | C27: ='Dot Product'!C29/1000000 -> 0.0082423136 | D27: ='Dot Product'!D29/1000000 -> 0.0081774639 | E27: ='Dot Product'!E29/1000000 -> 316616.96 | F27: ='Dot Product'!F29/1000000 -> 358354.14 | G27: ='Dot Product'!G29/1000000 -> 29298.233 | H27: ='Dot Product'!H29/1000000 -> 28424549 | I27: ='Dot Product'!I29/1000000 -> 18265416 | ... P27: ='Dot Product'!P29/1000000 -> 27188.627
A28: Cdc42bpa | B28: ='Dot Product'!B6/1000000 -> 65538.93 | C28: ='Dot Product'!C6/1000000 -> 266.6232 | D28: ='Dot Product'!D6/1000000 -> 258.34429 | E28: ='Dot Product'!E6/1000000 -> 2890.7195 | F28: ='Dot Product'!F6/1000000 -> 34821.315 | G28: ='Dot Product'!G6/1000000 -> 40098.604 | H28: ='Dot Product'!H6/1000000 -> 116823.16 | I28: ='Dot Product'!I6/1000000 -> 98986.843 | ... P28: ='Dot Product'!P6/1000000 -> 87657.379
A29: Rps6ka4 | B29: ='Dot Product'!B34/1000000 -> 65517.515 | C29: ='Dot Product'!C34/1000000 -> 338.26684 | D29: ='Dot Product'!D34/1000000 -> 121.91104 | E29: ='Dot Product'!E34/1000000 -> 3665.3017 | F29: ='Dot Product'!F34/1000000 -> 46158.296 | G29: ='Dot Product'!G34/1000000 -> 79988.896 | H29: ='Dot Product'!H34/1000000 -> 711796.47 | I29: ='Dot Product'!I34/1000000 -> 503683.9 | ... P29: ='Dot Product'!P34/1000000 -> 116782.92
A30: Rps6ka2 | B30: ='Dot Product'!B45/1000000 -> 60874.429 | C30: ='Dot Product'!C45/1000000 -> 3051.1971 | D30: ='Dot Product'!D45/1000000 -> 405.71033 | E30: ='Dot Product'!E45/1000000 -> 32883.534 | F30: ='Dot Product'!F45/1000000 -> 39822.49 | G30: ='Dot Product'!G45/1000000 -> 447309.74 | H30: ='Dot Product'!H45/1000000 -> 262241.2 | I30: ='Dot Product'!I45/1000000 -> 181737.73 | ... P30: ='Dot Product'!P45/1000000 -> 937606.22
A31: Prkcz | B31: ='Dot Product'!B27/1000000 -> 46243.485 | C31: ='Dot Product'!C27/1000000 -> 0.0010655067 | D31: ='Dot Product'!D27/1000000 -> 94.963872 | E31: ='Dot Product'!E27/1000000 -> 16.240621 | F31: ='Dot Product'!F27/1000000 -> 27666.801 | G31: ='Dot Product'!G27/1000000 -> 1603.6501 | H31: ='Dot Product'!H27/1000000 -> 98489.204 | I31: ='Dot Product'!I27/1000000 -> 86836.317 | ... P31: ='Dot Product'!P27/1000000 -> 5297.0534
A32: Stk38 | B32: ='Dot Product'!B36/1000000 -> 38465.721 | C32: ='Dot Product'!C36/1000000 -> 1909.4406 | D32: ='Dot Product'!D36/1000000 -> 78.997255 | E32: ='Dot Product'!E36/1000000 -> 20586.127 | F32: ='Dot Product'!F36/1000000 -> 32259.921 | G32: ='Dot Product'!G36/1000000 -> 274562.05 | H32: ='Dot Product'!H36/1000000 -> 84018.454 | I32: ='Dot Product'!I36/1000000 -> 73463.128 | ... P32: ='Dot Product'!P36/1000000 -> 587410.32
A33: Prkca | B33: ='Dot Product'!B2/1000000 -> 36049.139 | C33: ='Dot Product'!C2/1000000 -> 0.00071482149 | D33: ='Dot Product'!D2/1000000 -> 282.14151 | E33: ='Dot Product'!E2/1000000 -> 4.4690889 | F33: ='Dot Product'!F2/1000000 -> 12014.706 | G33: ='Dot Product'!G2/1000000 -> 701.95755 | H33: ='Dot Product'!H2/1000000 -> 38017.155 | I33: ='Dot Product'!I2/1000000 -> 26910.942 | ... P33: ='Dot Product'!P2/1000000 -> 2015.7887
A34: Rock1 | B34: ='Dot Product'!B51/1000000 -> 29218.985 | C34: ='Dot Product'!C51/1000000 -> 2345.4517 | D34: ='Dot Product'!D51/1000000 -> 55.505172 | E34: ='Dot Product'!E51/1000000 -> 25279.151 | F34: ='Dot Product'!F51/1000000 -> 31773.546 | G34: ='Dot Product'!G51/1000000 -> 353485.32 | H34: ='Dot Product'!H51/1000000 -> 393235.44 | I34: ='Dot Product'!I51/1000000 -> 274665.08 | ... P34: ='Dot Product'!P51/1000000 -> 722898.39
A35: Adrbk1 | B35: ='Dot Product'!B47/1000000 -> 28997.141 | C35: ='Dot Product'!C47/1000000 -> 1473.9205 | D35: ='Dot Product'!D47/1000000 -> 150.92017 | E35: ='Dot Product'!E47/1000000 -> 15886.828 | F35: ='Dot Product'!F47/1000000 -> 20322.79 | G35: ='Dot Product'!G47/1000000 -> 211863.59 | H35: ='Dot Product'!H47/1000000 -> 50064.216 | I35: ='Dot Product'!I47/1000000 -> 39956.952 | ... P35: ='Dot Product'!P47/1000000 -> 452459.88
A36: Rps6ka5 | B36: ='Dot Product'!B44/1000000 -> 28898.128 | C36: ='Dot Product'!C44/1000000 -> 1122.8818 | D36: ='Dot Product'!D44/1000000 -> 210.50428 | E36: ='Dot Product'!E44/1000000 -> 12101.991 | F36: ='Dot Product'!F44/1000000 -> 16342.853 | G36: ='Dot Product'!G44/1000000 -> 164704.72 | H36: ='Dot Product'!H44/1000000 -> 101225.75 | I36: ='Dot Product'!I44/1000000 -> 69565.887 | ... P36: ='Dot Product'!P44/1000000 -> 345307.62
A37: Prkce | B37: ='Dot Product'!B26/1000000 -> 25779.678 | C37: ='Dot Product'!C26/1000000 -> 0.00059292595 | D37: ='Dot Product'!D26/1000000 -> 52.940168 | E37: ='Dot Product'!E26/1000000 -> 9.0535989 | F37: ='Dot Product'!F26/1000000 -> 15423.604 | G37: ='Dot Product'!G26/1000000 -> 893.9978 | H37: ='Dot Product'!H26/1000000 -> 54905.447 | I37: ='Dot Product'!I26/1000000 -> 48409.237 | ... P37: ='Dot Product'!P26/1000000 -> 2952.9849
A38: Chek1 | B38: ='Dot Product'!B5/1000000 -> 25637.982 | C38: ='Dot Product'!C5/1000000 -> 62.850562 | D38: ='Dot Product'!D5/1000000 -> 139.25062 | E38: ='Dot Product'!E5/1000000 -> 682.77031 | F38: ='Dot Product'!F5/1000000 -> 11667.947 | G38: ='Dot Product'!G5/1000000 -> 9654.3994 | H38: ='Dot Product'!H5/1000000 -> 38545.134 | I38: ='Dot Product'!I5/1000000 -> 31214.142 | ... P38: ='Dot Product'!P5/1000000 -> 21247.087
A39: Adrbk2 | B39: ='Dot Product'!B13/1000000 -> 21568.603 | C39: ='Dot Product'!C13/1000000 -> 505.04433 | D39: ='Dot Product'!D13/1000000 -> 130.02904 | E39: ='Dot Product'!E13/1000000 -> 5445.635 | F39: ='Dot Product'!F13/1000000 -> 11414.366 | G39: ='Dot Product'!G13/1000000 -> 72790.559 | H39: ='Dot Product'!H13/1000000 -> 30523.627 | I39: ='Dot Product'!I13/1000000 -> 24027.101 | ... P39: ='Dot Product'!P13/1000000 -> 155803.63
A40: Pkn1 | B40: ='Dot Product'!B23/1000000 -> 17152.416 | C40: ='Dot Product'!C23/1000000 -> 245.53187 | D40: ='Dot Product'!D23/1000000 -> 26.852408 | E40: ='Dot Product'!E23/1000000 -> 2649.9724 | F40: ='Dot Product'!F23/1000000 -> 14977.791 | G40: ='Dot Product'!G23/1000000 -> 55153.66 | H40: ='Dot Product'!H23/1000000 -> 415772.39 | I40: ='Dot Product'!I23/1000000 -> 284470.99 | ... P40: ='Dot Product'!P23/1000000 -> 80905.856
...
