Workbook

Sheet Readme
A1: Dot products for all proline-directed protein kinases in mpkCCD versus all potential substrates that are regulated by vasopressin.

Sheet ProSub
A1: Gene Names | B1: 1K | C1: 4K | D1: 17K | E1: 200Kp | F1: 200Ks | G1: Group | J1: Ahnak | K1: Aqp2 | L1: Cobll1 | M1: Cxadr | N1: Epb4.1l1 | O1: Fam207a | P1: Kif13b | Q1: Lrrc16a | R1: Marcks | S1: Mylk | T1: Ppl | U1: Slc9a3r1 | V1: Tjp1
A2: Mapk13 | B2: 0.02 | C2: 101095.34 | D2: 161209.11 | E2: 291951.77 | F2: 1235417.8 | G2: CMGC | J2: 17698484 | K2: 545393.03 | L2: 0.01 | M2: 0.06 | N2: 21703.02 | O2: 0.04 | P2: 14357.66 | Q2: 722.61 | R2: 1026967.5 | S2: 82334.1 | T2: 2452108.7 | U2: 1055968.1 | V2: 69059.2
A3: Cdk5 | B3: 0.03 | C3: 121961.45 | D3: 137640.8 | E3: 185043.36 | F3: 1339012.6 | G3: CMGC | J3: 6254713.9 | K3: 3354707 | L3: 16.19 | M3: 980087.89 | N3: 11298.41 | O3: 0.04 | P3: 21100.27 | Q3: 36023.36 | R3: 328087.65 | S3: 13573.75 | T3: 93651.61 | U3: 286758.53 | V3: 2319.47
A4: Cdk17 | B4: 0.02 | C4: 45005.4 | D4: 70065.76 | E4: 140680.71 | F4: 589204.25 | G4: CMGC | J4: 19553888 | K4: 2850345.6 | L4: 66768.24 | M4: 1424359.2 | N4: 63149.06 | O4: 0.04 | P4: 56904.5 | Q4: 133970.8 | R4: 847067.2 | S4: 27569.5 | T4: 277951.9 | U4: 1894652.9 | V4: 3321.51
A5: Cdk16 | B5: 0.02 | C5: 45067.95 | D5: 64098.66 | E5: 82440.33 | F5: 620768.77 | G5: CMGC | J5: 2310375.2 | K5: 73387.84 | L5: 221962.02 | M5: 0.06 | N5: 0.01 | O5: 42564.97 | P5: 328546.03 | Q5: 151648.33 | R5: 563439.62 | S5: 41811.71 | T5: 8988.07 | U5: 118690.69 | V5: 14682.05
A6: Cdk18 | B6: 0.02 | C6: 58610.99 | D6: 88418.32 | E6: 264456.67 | F6: 668520.21 | G6: CMGC | J6: 34144576 | K6: 0.03 | L6: 70317.45 | M6: 3346.78 | N6: 230419.96 | O6: 113949.16 | P6: 660891.9 | Q6: 28323.83 | R6: 57474.37 | S6: 613056.26 | T6: 232774.22 | U6: 11457478 | V6: 112534.79
A7: Ick | B7: 0.01 | C7: 32296.84 | D7: 49146.66 | E7: 61859.48 | F7: 491719.24 | G7: CMGC | J7: Substrate | K7: Substrate | L7: Substrate | M7: Substrate | N7: Substrate | O7: Substrate | P7: Substrate | Q7: Substrate | R7: Substrate | S7: Substrate | T7: Substrate | U7: Substrate | V7: Substrate
A8: Cdk12 | B8: 0.01 | C8: 16148.42 | D8: 24573.33 | E8: 30929.74 | F8: 245859.62 | G8: CMGC
A9: Cdk14 | B9: 0.02 | C9: 42656.2 | D9: 64910.69 | E9: 81701.2 | F9: 649440.51 | G9: CMGC
A10: Cdk20 | B10: 0.03 | C10: 59494.18 | D10: 90533.32 | E10: 113951.68 | F10: 905798.6 | G10: CMGC
A11: Mak | B11: 0.02 | C11: 36464.17 | D11: 55488.17 | E11: 69841.35 | F11: 555166.88 | G11: CMGC
A12: Cdk13 | B12: 0.01 | C12: 14308.73 | D12: 21773.84 | E12: 27406.1 | F12: 220426 | G12: CMGC
A13: Gsk3b | B13: 0.02 | C13: 46236.24 | D13: 80949.64 | E13: 139851.24 | F13: 752171.78 | G13: CMGC
A14: Cdk15 | B14: 0.02 | C14: 47099.56 | D14: 71916.1 | E14: 131310.09 | F14: 717090.56 | G14: CMGC
A15: Cdk2 | B15: 51687.6 | C15: 136363.81 | D15: 211578.89 | E15: 412648.71 | F15: 2288054.1 | G15: CMGC
A16: Mapk6 | B16: 0.01 | C16: 2214.81 | D16: 14918.74 | E16: 6488.57 | F16: 12407.36 | G16: CMGC
A17: Mapk4 | B17: 0.02 | C17: 2794.07 | D17: 18820.56 | E17: 8185.58 | F17: 15652.37 | G17: CMGC
A18: Srpk1 | B18: 0.01 | C18: 19216.58 | D18: 159742.44 | E18: 340878.25 | F18: 0.01 | G18: CMGC
A19: Cdk9 | B19: 0.02 | C19: 52576.25 | D19: 100016.24 | E19: 847110.61 | F19: 952398.7 | G19: CMGC
... A56: Tjp1 | B56: 69059.2 | C56: 2319.47 | D56: 3321.51 | E56: 14682.05 | F56: 112534.79 | G56: Substrate

Sheet Dot Product
A1: Gene Names | B1: Ahnak | C1: Aqp2 | D1: Cobll1 | E1: Cxadr | F1: Epb4.1l1 | G1: Fam207a | H1: Kif13b | I1: Lrrc16a | J1: Marcks | K1: Mylk | L1: Ppl | M1: Slc9a3r1 | N1: Tjp1
A2: Mapk13 | B2: =SUMPRODUCT(ProSub!$B2:$F2, ProSub!$B$44:$F$44) -> 4.6641923e+13 | C2: =SUMPRODUCT(ProSub!$B2:$F2, ProSub!$B$45:$F$45) -> 8.2007268e+11 | D2: =SUMPRODUCT(ProSub!$B2:$F2, ProSub!$B$46:$F$46) -> 1.6243892e+11 | E2: =SUMPRODUCT(ProSub!$B2:$F2, ProSub!$B$47:$F$47) -> 3.3283668e+11 | F2: =SUMPRODUCT(ProSub!$B2:$F2, ProSub!$B$48:$F$48) -> 2.9598735e+11 | G2: =SUMPRODUCT(ProSub!$B2:$F2, ProSub!$B$49:$F$49) -> 1.5320175e+11 | H2: =SUMPRODUCT(ProSub!$B2:$F2, ProSub!$B$50:$F$50) -> 9.2370388e+11 | I2: =SUMPRODUCT(ProSub!$B2:$F2, ProSub!$B$51:$F$51) -> 1.0450487e+11 | J2: =SUMPRODUCT(ProSub!$B2:$F2, ProSub!$B$52:$F$52) -> 4.0522516e+11 | K2: =SUMPRODUCT(ProSub!$B2:$F2, ProSub!$B$53:$F$53) -> 7.7540432e+11 | L2: =SUMPRODUCT(ProSub!$B2:$F2, ProSub!$B$54:$F$54) -> 3.4447367e+11 | M2: =SUMPRODUCT(ProSub!$B2:$F2, ProSub!$B$55:$F$55) -> 1.452385e+13 | N2: =SUMPRODUCT(ProSub!$B2:$F2, ProSub!$B$56:$F$56) -> 1.4408388e+11
A3: Cdk5 | B3: =SUMPRODUCT(ProSub!$B3:$F3, ProSub!$B$44:$F$44) -> 4.9601783e+13 | C3: =SUMPRODUCT(ProSub!$B3:$F3, ProSub!$B$45:$F$45) -> 8.1504876e+11 | D3: =SUMPRODUCT(ProSub!$B3:$F3, ProSub!$B$46:$F$46) -> 1.4442056e+11 | E3: =SUMPRODUCT(ProSub!$B3:$F3, ProSub!$B$47:$F$47) -> 3.2006427e+11 | F3: =SUMPRODUCT(ProSub!$B3:$F3, ProSub!$B$48:$F$48) -> 3.1860508e+11 | G3: =SUMPRODUCT(ProSub!$B3:$F3, ProSub!$B$49:$F$49) -> 1.6045573e+11 | H3: =SUMPRODUCT(ProSub!$B3:$F3, ProSub!$B$50:$F$50) -> 9.5614362e+11 | I3: =SUMPRODUCT(ProSub!$B3:$F3, ProSub!$B$51:$F$51) -> 8.882079e+10 | J3: =SUMPRODUCT(ProSub!$B3:$F3, ProSub!$B$52:$F$52) -> 3.3782475e+11 | K3: =SUMPRODUCT(ProSub!$B3:$F3, ProSub!$B$53:$F$53) -> 8.3407718e+11 | L3: =SUMPRODUCT(ProSub!$B3:$F3, ProSub!$B$54:$F$54) -> 3.6303027e+11 | M3: =SUMPRODUCT(ProSub!$B3:$F3, ProSub!$B$55:$F$55) -> 1.5659425e+13 | N3: =SUMPRODUCT(ProSub!$B3:$F3, ProSub!$B$56:$F$56) -> 1.5414238e+11
A4: Cdk17 | B4: =SUMPRODUCT(ProSub!$B4:$F4, ProSub!$B$44:$F$44) -> 2.2094709e+13 | C4: =SUMPRODUCT(ProSub!$B4:$F4, ProSub!$B$45:$F$45) -> 3.6101584e+11 | D4: =SUMPRODUCT(ProSub!$B4:$F4, ProSub!$B$46:$F$46) -> 7.7336011e+10 | E4: =SUMPRODUCT(ProSub!$B4:$F4, ProSub!$B$47:$F$47) -> 1.4588e+11 | F4: =SUMPRODUCT(ProSub!$B4:$F4, ProSub!$B$48:$F$48) -> 1.406975e+11 | G4: =SUMPRODUCT(ProSub!$B4:$F4, ProSub!$B$49:$F$49) -> 7.3127404e+10 | H4: =SUMPRODUCT(ProSub!$B4:$F4, ProSub!$B$50:$F$50) -> 4.4055709e+11 | I4: =SUMPRODUCT(ProSub!$B4:$F4, ProSub!$B$51:$F$51) -> 4.9030527e+10 | J4: =SUMPRODUCT(ProSub!$B4:$F4, ProSub!$B$52:$F$52) -> 1.8724537e+11 | K4: =SUMPRODUCT(ProSub!$B4:$F4, ProSub!$B$53:$F$53) -> 3.6964003e+11 | L4: =SUMPRODUCT(ProSub!$B4:$F4, ProSub!$B$54:$F$54) -> 1.621058e+11 | M4: =SUMPRODUCT(ProSub!$B4:$F4, ProSub!$B$55:$F$55) -> 6.9131484e+12 | N4: =SUMPRODUCT(ProSub!$B4:$F4, ProSub!$B$56:$F$56) -> 6.8708572e+10
A5: Cdk16 | B5: =SUMPRODUCT(ProSub!$B5:$F5, ProSub!$B$44:$F$44) -> 2.292162e+13 | C5: =SUMPRODUCT(ProSub!$B5:$F5, ProSub!$B$45:$F$45) -> 3.3994325e+11 | D5: =SUMPRODUCT(ProSub!$B5:$F5, ProSub!$B$46:$F$46) -> 6.6229983e+10 | E5: =SUMPRODUCT(ProSub!$B5:$F5, ProSub!$B$47:$F$47) -> 1.3754765e+11 | F5: =SUMPRODUCT(ProSub!$B5:$F5, ProSub!$B$48:$F$48) -> 1.4759448e+11 | G5: =SUMPRODUCT(ProSub!$B5:$F5, ProSub!$B$49:$F$49) -> 7.4245154e+10 | H5: =SUMPRODUCT(ProSub!$B5:$F5, ProSub!$B$50:$F$50) -> 4.4194494e+11 | I5: =SUMPRODUCT(ProSub!$B5:$F5, ProSub!$B$51:$F$51) -> 4.0295335e+10 | J5: =SUMPRODUCT(ProSub!$B5:$F5, ProSub!$B$52:$F$52) -> 1.5121057e+11 | K5: =SUMPRODUCT(ProSub!$B5:$F5, ProSub!$B$53:$F$53) -> 3.8639206e+11 | L5: =SUMPRODUCT(ProSub!$B5:$F5, ProSub!$B$54:$F$54) -> 1.6727703e+11 | M5: =SUMPRODUCT(ProSub!$B5:$F5, ProSub!$B$55:$F$55) -> 7.256598e+12 | N5: =SUMPRODUCT(ProSub!$B5:$F5, ProSub!$B$56:$F$56) -> 7.1385916e+10
A6: Cdk18 | B6: =SUMPRODUCT(ProSub!$B6:$F6, ProSub!$B$44:$F$44) -> 2.5532851e+13 | C6: =SUMPRODUCT(ProSub!$B6:$F6, ProSub!$B$45:$F$45) -> 4.680534e+11 | D6: =SUMPRODUCT(ProSub!$B6:$F6, ProSub!$B$46:$F$46) -> 1.1161246e+11 | E6: =SUMPRODUCT(ProSub!$B6:$F6, ProSub!$B$47:$F$47) -> 1.8562077e+11 | F6: =SUMPRODUCT(ProSub!$B6:$F6, ProSub!$B$48:$F$48) -> 1.6028615e+11 | G6: =SUMPRODUCT(ProSub!$B6:$F6, ProSub!$B$49:$F$49) -> 8.7433912e+10 | H6: =SUMPRODUCT(ProSub!$B6:$F6, ProSub!$B$50:$F$50) -> 5.3497389e+11 | I6: =SUMPRODUCT(ProSub!$B6:$F6, ProSub!$B$51:$F$51) -> 7.2996303e+10 | J6: =SUMPRODUCT(ProSub!$B6:$F6, ProSub!$B$52:$F$52) -> 2.8155396e+11 | K6: =SUMPRODUCT(ProSub!$B6:$F6, ProSub!$B$53:$F$53) -> 4.2413111e+11 | L6: =SUMPRODUCT(ProSub!$B6:$F6, ProSub!$B$54:$F$54) -> 1.8805633e+11 | M6: =SUMPRODUCT(ProSub!$B6:$F6, ProSub!$B$55:$F$55) -> 7.8752736e+12 | N6: =SUMPRODUCT(ProSub!$B6:$F6, ProSub!$B$56:$F$56) -> 7.9544178e+10
A7: Ick | B7: =SUMPRODUCT(ProSub!$B7:$F7, ProSub!$B$44:$F$44) -> 1.809548e+13 | C7: =SUMPRODUCT(ProSub!$B7:$F7, ProSub!$B$45:$F$45) -> 2.5297115e+11 | D7: =SUMPRODUCT(ProSub!$B7:$F7, ProSub!$B$46:$F$46) -> 5.1588857e+10 | E7: =SUMPRODUCT(ProSub!$B7:$F7, ProSub!$B$47:$F$47) -> 1.0330192e+11 | F7: =SUMPRODUCT(ProSub!$B7:$F7, ProSub!$B$48:$F$48) -> 1.167704e+11 | G7: =SUMPRODUCT(ProSub!$B7:$F7, ProSub!$B$49:$F$49) -> 5.8664045e+10 | H7: =SUMPRODUCT(ProSub!$B7:$F7, ProSub!$B$50:$F$50) -> 3.4877509e+11 | I7: =SUMPRODUCT(ProSub!$B7:$F7, ProSub!$B$51:$F$51) -> 3.1055917e+10 | J7: =SUMPRODUCT(ProSub!$B7:$F7, ProSub!$B$52:$F$52) -> 1.1534206e+11 | K7: =SUMPRODUCT(ProSub!$B7:$F7, ProSub!$B$53:$F$53) -> 3.0583135e+11 | L7: =SUMPRODUCT(ProSub!$B7:$F7, ProSub!$B$54:$F$54) -> 1.3170064e+11 | M7: =SUMPRODUCT(ProSub!$B7:$F7, ProSub!$B$55:$F$55) -> 5.7435819e+12 | N7: =SUMPRODUCT(ProSub!$B7:$F7, ProSub!$B$56:$F$56) -> 5.6481899e+10
A8: Cdk12 | B8: =SUMPRODUCT(ProSub!$B8:$F8, ProSub!$B$44:$F$44) -> 9.0477399e+12 | C8: =SUMPRODUCT(ProSub!$B8:$F8, ProSub!$B$45:$F$45) -> 1.2648558e+11 | D8: =SUMPRODUCT(ProSub!$B8:$F8, ProSub!$B$46:$F$46) -> 2.5794429e+10 | E8: =SUMPRODUCT(ProSub!$B8:$F8, ProSub!$B$47:$F$47) -> 5.1650959e+10 | F8: =SUMPRODUCT(ProSub!$B8:$F8, ProSub!$B$48:$F$48) -> 5.8385198e+10 | G8: =SUMPRODUCT(ProSub!$B8:$F8, ProSub!$B$49:$F$49) -> 2.9332022e+10 | H8: =SUMPRODUCT(ProSub!$B8:$F8, ProSub!$B$50:$F$50) -> 1.7438754e+11 | I8: =SUMPRODUCT(ProSub!$B8:$F8, ProSub!$B$51:$F$51) -> 1.5527959e+10 | J8: =SUMPRODUCT(ProSub!$B8:$F8, ProSub!$B$52:$F$52) -> 5.7671037e+10 | K8: =SUMPRODUCT(ProSub!$B8:$F8, ProSub!$B$53:$F$53) -> 1.5291567e+11 | L8: =SUMPRODUCT(ProSub!$B8:$F8, ProSub!$B$54:$F$54) -> 6.5850334e+10 | M8: =SUMPRODUCT(ProSub!$B8:$F8, ProSub!$B$55:$F$55) -> 2.871791e+12 | N8: =SUMPRODUCT(ProSub!$B8:$F8, ProSub!$B$56:$F$56) -> 2.824095e+10
A9: Cdk14 | B9: =SUMPRODUCT(ProSub!$B9:$F9, ProSub!$B$44:$F$44) -> 2.389969e+13 | C9: =SUMPRODUCT(ProSub!$B9:$F9, ProSub!$B$45:$F$45) -> 3.3411286e+11 | D9: =SUMPRODUCT(ProSub!$B9:$F9, ProSub!$B$46:$F$46) -> 6.8136227e+10 | E9: =SUMPRODUCT(ProSub!$B9:$F9, ProSub!$B$47:$F$47) -> 1.364365e+11 | F9: =SUMPRODUCT(ProSub!$B9:$F9, ProSub!$B$48:$F$48) -> 1.5422505e+11 | G9: =SUMPRODUCT(ProSub!$B9:$F9, ProSub!$B$49:$F$49) -> 7.7480814e+10 | H9: =SUMPRODUCT(ProSub!$B9:$F9, ProSub!$B$50:$F$50) -> 4.6064635e+11 | I9: =SUMPRODUCT(ProSub!$B9:$F9, ProSub!$B$51:$F$51) -> 4.101725e+10 | J9: =SUMPRODUCT(ProSub!$B9:$F9, ProSub!$B$52:$F$52) -> 1.5233859e+11 | K9: =SUMPRODUCT(ProSub!$B9:$F9, ProSub!$B$53:$F$53) -> 4.039282e+11 | L9: =SUMPRODUCT(ProSub!$B9:$F9, ProSub!$B$54:$F$54) -> 1.7394426e+11 | M9: =SUMPRODUCT(ProSub!$B9:$F9, ProSub!$B$55:$F$55) -> 7.585863e+12 | N9: =SUMPRODUCT(ProSub!$B9:$F9, ProSub!$B$56:$F$56) -> 7.4598735e+10
A10: Cdk20 | B10: =SUMPRODUCT(ProSub!$B10:$F10, ProSub!$B$44:$F$44) -> 3.3333778e+13 | C10: =SUMPRODUCT(ProSub!$B10:$F10, ProSub!$B$45:$F$45) -> 4.659995e+11 | D10: =SUMPRODUCT(ProSub!$B10:$F10, ProSub!$B$46:$F$46) -> 9.5032106e+10 | E10: =SUMPRODUCT(ProSub!$B10:$F10, ProSub!$B$47:$F$47) -> 1.9029301e+11 | F10: =SUMPRODUCT(ProSub!$B10:$F10, ProSub!$B$48:$F$48) -> 2.1510336e+11 | G10: =SUMPRODUCT(ProSub!$B10:$F10, ProSub!$B$49:$F$49) -> 1.0806535e+11 | H10: =SUMPRODUCT(ProSub!$B10:$F10, ProSub!$B$50:$F$50) -> 6.4248043e+11 | I10: =SUMPRODUCT(ProSub!$B10:$F10, ProSub!$B$51:$F$51) -> 5.7208269e+10 | J10: =SUMPRODUCT(ProSub!$B10:$F10, ProSub!$B$52:$F$52) -> 2.1247224e+11 | K10: =SUMPRODUCT(ProSub!$B10:$F10, ProSub!$B$53:$F$53) -> 5.6337354e+11 | L10: =SUMPRODUCT(ProSub!$B10:$F10, ProSub!$B$54:$F$54) -> 2.4260648e+11 | M10: =SUMPRODUCT(ProSub!$B10:$F10, ProSub!$B$55:$F$55) -> 1.0580283e+13 | N10: =SUMPRODUCT(ProSub!$B10:$F10, ProSub!$B$56:$F$56) -> 1.040456e+11
A11: Mak | B11: =SUMPRODUCT(ProSub!$B11:$F11, ProSub!$B$44:$F$44) -> 2.043038e+13 | C11: =SUMPRODUCT(ProSub!$B11:$F11, ProSub!$B$45:$F$45) -> 2.856126e+11 | D11: =SUMPRODUCT(ProSub!$B11:$F11, ProSub!$B$46:$F$46) -> 5.8245484e+10 | E11: =SUMPRODUCT(ProSub!$B11:$F11, ProSub!$B$47:$F$47) -> 1.166312e+11 | F11: =SUMPRODUCT(ProSub!$B11:$F11, ProSub!$B$48:$F$48) -> 1.3183754e+11 | G11: =SUMPRODUCT(ProSub!$B11:$F11, ProSub!$B$49:$F$49) -> 6.6233598e+10 | H11: =SUMPRODUCT(ProSub!$B11:$F11, ProSub!$B$50:$F$50) -> 3.9377832e+11 | I11: =SUMPRODUCT(ProSub!$B11:$F11, ProSub!$B$51:$F$51) -> 3.5063133e+10 | J11: =SUMPRODUCT(ProSub!$B11:$F11, ProSub!$B$52:$F$52) -> 1.3022492e+11 | K11: =SUMPRODUCT(ProSub!$B11:$F11, ProSub!$B$53:$F$53) -> 3.4529346e+11 | L11: =SUMPRODUCT(ProSub!$B11:$F11, ProSub!$B$54:$F$54) -> 1.486943e+11 | M11: =SUMPRODUCT(ProSub!$B11:$F11, ProSub!$B$55:$F$55) -> 6.4846893e+12 | N11: =SUMPRODUCT(ProSub!$B11:$F11, ProSub!$B$56:$F$56) -> 6.3769886e+10
A12: Cdk13 | B12: =SUMPRODUCT(ProSub!$B12:$F12, ProSub!$B$44:$F$44) -> 8.1049311e+12 | C12: =SUMPRODUCT(ProSub!$B12:$F12, ProSub!$B$45:$F$45) -> 1.1207585e+11 | D12: =SUMPRODUCT(ProSub!$B12:$F12, ProSub!$B$46:$F$46) -> 2.303694e+10 | E12: =SUMPRODUCT(ProSub!$B12:$F12, ProSub!$B$47:$F$47) -> 4.5775301e+10 | F12: =SUMPRODUCT(ProSub!$B12:$F12, ProSub!$B$48:$F$48) -> 5.2327214e+10 | G12: =SUMPRODUCT(ProSub!$B12:$F12, ProSub!$B$49:$F$49) -> 2.6283899e+10 | H12: =SUMPRODUCT(ProSub!$B12:$F12, ProSub!$B$50:$F$50) -> 1.5622287e+11 | I12: =SUMPRODUCT(ProSub!$B12:$F12, ProSub!$B$51:$F$51) -> 1.3831905e+10 | J12: =SUMPRODUCT(ProSub!$B12:$F12, ProSub!$B$52:$F$52) -> 5.1248962e+10 | K12: =SUMPRODUCT(ProSub!$B12:$F12, ProSub!$B$53:$F$53) -> 1.3707395e+11 | L12: =SUMPRODUCT(ProSub!$B12:$F12, ProSub!$B$54:$F$54) -> 5.8947958e+10 | M12: =SUMPRODUCT(ProSub!$B12:$F12, ProSub!$B$55:$F$55) -> 2.574136e+12 | N12: =SUMPRODUCT(ProSub!$B12:$F12, ProSub!$B$56:$F$56) -> 2.5313483e+10
A13: Gsk3b | B13: =SUMPRODUCT(ProSub!$B13:$F13, ProSub!$B$44:$F$44) -> 2.787777e+13 | C13: =SUMPRODUCT(ProSub!$B13:$F13, ProSub!$B$45:$F$45) -> 3.961069e+11 | D13: =SUMPRODUCT(ProSub!$B13:$F13, ProSub!$B$46:$F$46) -> 8.9338079e+10 | E13: =SUMPRODUCT(ProSub!$B13:$F13, ProSub!$B$47:$F$47) -> 1.631343e+11 | F13: =SUMPRODUCT(ProSub!$B13:$F13, ProSub!$B$48:$F$48) -> 1.7894968e+11 | G13: =SUMPRODUCT(ProSub!$B13:$F13, ProSub!$B$49:$F$49) -> 9.1662111e+10 | H13: =SUMPRODUCT(ProSub!$B13:$F13, ProSub!$B$50:$F$50) -> 5.486338e+11 | I13: =SUMPRODUCT(ProSub!$B13:$F13, ProSub!$B$51:$F$51) -> 5.5023065e+10 | J13: =SUMPRODUCT(ProSub!$B13:$F13, ProSub!$B$52:$F$52) -> 2.0576767e+11 | K13: =SUMPRODUCT(ProSub!$B13:$F13, ProSub!$B$53:$F$53) -> 4.6983038e+11 | L13: =SUMPRODUCT(ProSub!$B13:$F13, ProSub!$B$54:$F$54) -> 2.0317345e+11 | M13: =SUMPRODUCT(ProSub!$B13:$F13, ProSub!$B$55:$F$55) -> 8.801221e+12 | N13: =SUMPRODUCT(ProSub!$B13:$F13, ProSub!$B$56:$F$56) -> 8.7074916e+10
... A42: Gsk3a | B42: =SUMPRODUCT(ProSub!$B42:$F42, ProSub!$B$44:$F$44) -> 3.0624517e+12 | C42: =SUMPRODUCT(ProSub!$B42:$F42, ProSub!$B$45:$F$45) -> 3.6575095e+10 | D42: =SUMPRODUCT(ProSub!$B42:$F42, ProSub!$B$46:$F$46) -> 6.7664753e+09 | E42: =SUMPRODUCT(ProSub!$B42:$F42, ProSub!$B$47:$F$47) -> 1.1203437e+10 | F42: =SUMPRODUCT(ProSub!$B42:$F42, ProSub!$B$48:$F$48) -> 2.0269256e+10 | G42: =SUMPRODUCT(ProSub!$B42:$F42, ProSub!$B$49:$F$49) -> 1.0064366e+10 | H42: =SUMPRODUCT(ProSub!$B42:$F42, ProSub!$B$50:$F$50) -> 5.8838178e+10 | I42: =SUMPRODUCT(ProSub!$B42:$F42, ProSub!$B$51:$F$51) -> 3.3192524e+09 | J42: =SUMPRODUCT(ProSub!$B42:$F42, ProSub!$B$52:$F$52) -> 1.0356387e+10 | K42: =SUMPRODUCT(ProSub!$B42:$F42, ProSub!$B$53:$F$53) -> 5.3801082e+10 | L42: =SUMPRODUCT(ProSub!$B42:$F42, ProSub!$B$54:$F$54) -> 2.1461273e+10 | M42: =SUMPRODUCT(ProSub!$B42:$F42, ProSub!$B$55:$F$55) -> 1.0047262e+12 | N42: =SUMPRODUCT(ProSub!$B42:$F42, ProSub!$B$56:$F$56) -> 9.8920412e+09

Sheet ProSub_dotProduct
A1: Gene Symbol | B1: Ahnak | C1: Aqp2 | D1: Cobll1 | E1: Cxadr | F1: Epb4.1l1 | G1: Fam207a | H1: Kif13b | I1: Lrrc16a | J1: Marcks | K1: Mylk | L1: Ppl | M1: Slc9a3r1 | N1: Tjp1
A2: Cdk1 | B2: ='Dot Product'!B28/1000000 -> 1.4465406e+08 | C2: ='Dot Product'!C28/1000000 -> 2551428.6 | D2: ='Dot Product'!D28/1000000 -> 578243.41 | E2: ='Dot Product'!E28/1000000 -> 937832.59 | F2: ='Dot Product'!F28/1000000 -> 911885.11 | G2: ='Dot Product'!G28/1000000 -> 491014.03 | H2: ='Dot Product'!H28/1000000 -> 2982946.4 | I2: ='Dot Product'!I28/1000000 -> 366808.18 | ... N2: ='Dot Product'!N28/1000000 -> 456547.1
A3: Mapk1 | B3: ='Dot Product'!B38/1000000 -> 2.7781498e+08 | C3: ='Dot Product'!C38/1000000 -> 2504737.2 | D3: ='Dot Product'!D38/1000000 -> 1303552.2 | E3: ='Dot Product'!E38/1000000 -> 1037127.9 | F3: ='Dot Product'!F38/1000000 -> 1750456 | G3: ='Dot Product'!G38/1000000 -> 983721.07 | H3: ='Dot Product'!H38/1000000 -> 6020488.4 | I3: ='Dot Product'!I38/1000000 -> 806190.41 | ... N3: ='Dot Product'!N38/1000000 -> 900093.74
A4: Mapk3 | B4: ='Dot Product'!B37/1000000 -> 2.4858302e+08 | C4: ='Dot Product'!C37/1000000 -> 2293321.8 | D4: ='Dot Product'!D37/1000000 -> 1116550.7 | E4: ='Dot Product'!E37/1000000 -> 930092.32 | F4: ='Dot Product'!F37/1000000 -> 1570152.9 | G4: ='Dot Product'!G37/1000000 -> 873301.41 | H4: ='Dot Product'!H37/1000000 -> 5328026 | I4: ='Dot Product'!I37/1000000 -> 685870.07 | ... N4: ='Dot Product'!N37/1000000 -> 804826.86
A5: Cdk2 | B5: ='Dot Product'!B15/1000000 -> 84982908 | C5: ='Dot Product'!C15/1000000 -> 1119007.1 | D5: ='Dot Product'!D15/1000000 -> 266611.43 | E5: ='Dot Product'!E15/1000000 -> 442670.49 | F5: ='Dot Product'!F15/1000000 -> 543236.81 | G5: ='Dot Product'!G15/1000000 -> 278286.23 | H5: ='Dot Product'!H15/1000000 -> 1663389.7 | I5: ='Dot Product'!I15/1000000 -> 160678.97 | ... N5: ='Dot Product'!N15/1000000 -> 268132.77
A6: Cdk4 | B6: ='Dot Product'!B30/1000000 -> 52804197 | C6: ='Dot Product'!C30/1000000 -> 821511.79 | D6: ='Dot Product'!D30/1000000 -> 249272.63 | E6: ='Dot Product'!E30/1000000 -> 308030.44 | F6: ='Dot Product'!F30/1000000 -> 333715.95 | G6: ='Dot Product'!G30/1000000 -> 187461.51 | H6: ='Dot Product'!H30/1000000 -> 1149327.3 | I6: ='Dot Product'!I30/1000000 -> 158402.07 | ... N6: ='Dot Product'!N30/1000000 -> 168387.48
A7: Cdk5 | B7: ='Dot Product'!B3/1000000 -> 49601783 | C7: ='Dot Product'!C3/1000000 -> 815048.76 | D7: ='Dot Product'!D3/1000000 -> 144420.56 | E7: ='Dot Product'!E3/1000000 -> 320064.27 | F7: ='Dot Product'!F3/1000000 -> 318605.08 | G7: ='Dot Product'!G3/1000000 -> 160455.73 | H7: ='Dot Product'!H3/1000000 -> 956143.62 | I7: ='Dot Product'!I3/1000000 -> 88820.79 | ... N7: ='Dot Product'!N3/1000000 -> 154142.38
A8: Mapk12 | B8: ='Dot Product'!B35/1000000 -> 68862728 | C8: ='Dot Product'!C35/1000000 -> 587596.43 | D8: ='Dot Product'!D35/1000000 -> 189446.32 | E8: ='Dot Product'!E35/1000000 -> 236480.97 | F8: ='Dot Product'!F35/1000000 -> 451625.86 | G8: ='Dot Product'!G35/1000000 -> 228558.07 | H8: ='Dot Product'!H35/1000000 -> 1350590.9 | I8: ='Dot Product'!I35/1000000 -> 103717.86 | ... N8: ='Dot Product'!N35/1000000 -> 220486.53
A9: Srpk1 | B9: ='Dot Product'!B18/1000000 -> 4031337.2 | C9: ='Dot Product'!C18/1000000 -> 544803.47 | D9: ='Dot Product'!D18/1000000 -> 86328.058 | E9: ='Dot Product'!E18/1000000 -> 246364.57 | F9: ='Dot Product'!F18/1000000 -> 10304.708 | G9: ='Dot Product'!G18/1000000 -> 14509.481 | H9: ='Dot Product'!H18/1000000 -> 121489.74 | I9: ='Dot Product'!I18/1000000 -> 73786.686 | ... N9: ='Dot Product'!N18/1000000 -> 5579.9517
A10: Mapk14 | B10: ='Dot Product'!B36/1000000 -> 93202507 | C10: ='Dot Product'!C36/1000000 -> 543387.06 | D10: ='Dot Product'!D36/1000000 -> 266549.78 | E10: ='Dot Product'!E36/1000000 -> 225963.14 | F10: ='Dot Product'!F36/1000000 -> 614268.4 | G10: ='Dot Product'!G36/1000000 -> 314172.63 | H10: ='Dot Product'!H36/1000000 -> 1856990.6 | I10: ='Dot Product'!I36/1000000 -> 142172.26 | ... N10: ='Dot Product'!N36/1000000 -> 301657.02
A11: Cdk9 | B11: ='Dot Product'!B19/1000000 -> 36760949 | C11: ='Dot Product'!C19/1000000 -> 523626.42 | D11: ='Dot Product'!D19/1000000 -> 261675.39 | E11: ='Dot Product'!E19/1000000 -> 197175.91 | F11: ='Dot Product'!F19/1000000 -> 226361.64 | G11: ='Dot Product'!G19/1000000 -> 144582.28 | H11: ='Dot Product'!H19/1000000 -> 914548.16 | I11: ='Dot Product'!I19/1000000 -> 170731.72 | ... N11: ='Dot Product'!N19/1000000 -> 120069.46
A12: Cdk6 | B12: ='Dot Product'!B29/1000000 -> 45121813 | C12: ='Dot Product'!C29/1000000 -> 483779.62 | D12: ='Dot Product'!D29/1000000 -> 120069.72 | E12: ='Dot Product'!E29/1000000 -> 199090.99 | F12: ='Dot Product'!F29/1000000 -> 294262.03 | G12: ='Dot Product'!G29/1000000 -> 147200.41 | H12: ='Dot Product'!H29/1000000 -> 869987.51 | I12: ='Dot Product'!I29/1000000 -> 67999.812 | ... N12: ='Dot Product'!N29/1000000 -> 142628.57
A13: Cdk18 | B13: ='Dot Product'!B6/1000000 -> 25532851 | C13: ='Dot Product'!C6/1000000 -> 468053.4 | D13: ='Dot Product'!D6/1000000 -> 111612.46 | E13: ='Dot Product'!E6/1000000 -> 185620.77 | F13: ='Dot Product'!F6/1000000 -> 160286.15 | G13: ='Dot Product'!G6/1000000 -> 87433.912 | H13: ='Dot Product'!H6/1000000 -> 534973.89 | I13: ='Dot Product'!I6/1000000 -> 72996.303 | ... N13: ='Dot Product'!N6/1000000 -> 79544.178
A14: Cdk20 | B14: ='Dot Product'!B10/1000000 -> 33333778 | C14: ='Dot Product'!C10/1000000 -> 465999.5 | D14: ='Dot Product'!D10/1000000 -> 95032.106 | E14: ='Dot Product'!E10/1000000 -> 190293.01 | F14: ='Dot Product'!F10/1000000 -> 215103.36 | G14: ='Dot Product'!G10/1000000 -> 108065.35 | H14: ='Dot Product'!H10/1000000 -> 642480.43 | I14: ='Dot Product'!I10/1000000 -> 57208.269 | ... N14: ='Dot Product'!N10/1000000 -> 104045.6
A15: Mapk11 | B15: ='Dot Product'!B32/1000000 -> 38078974 | C15: ='Dot Product'!C32/1000000 -> 420563.73 | D15: ='Dot Product'!D32/1000000 -> 127064.43 | E15: ='Dot Product'!E32/1000000 -> 172821.43 | F15: ='Dot Product'!F32/1000000 -> 246196.06 | G15: ='Dot Product'!G32/1000000 -> 127992.93 | H15: ='Dot Product'!H32/1000000 -> 765915.5 | I15: ='Dot Product'!I32/1000000 -> 75589.539 | ... N15: ='Dot Product'!N32/1000000 -> 120886.15
A16: Gsk3b | B16: ='Dot Product'!B13/1000000 -> 27877770 | C16: ='Dot Product'!C13/1000000 -> 396106.9 | D16: ='Dot Product'!D13/1000000 -> 89338.079 | E16: ='Dot Product'!E13/1000000 -> 163134.3 | F16: ='Dot Product'!F13/1000000 -> 178949.68 | G16: ='Dot Product'!G13/1000000 -> 91662.111 | H16: ='Dot Product'!H13/1000000 -> 548633.8 | I16: ='Dot Product'!I13/1000000 -> 55023.065 | ... N16: ='Dot Product'!N13/1000000 -> 87074.916
A17: Mapk9 | B17: ='Dot Product'!B34/1000000 -> 36242250 | C17: ='Dot Product'!C34/1000000 -> 392257.53 | D17: ='Dot Product'!D34/1000000 -> 121056.21 | E17: ='Dot Product'!E34/1000000 -> 161111.46 | F17: ='Dot Product'!F34/1000000 -> 234457.49 | G17: ='Dot Product'!G34/1000000 -> 121976.09 | H17: ='Dot Product'!H34/1000000 -> 729821.63 | I17: ='Dot Product'!I34/1000000 -> 71817.884 | ... N17: ='Dot Product'!N34/1000000 -> 115182.82
A18: Mapk8 | B18: ='Dot Product'!B31/1000000 -> 35482681 | C18: ='Dot Product'!C31/1000000 -> 391888.91 | D18: ='Dot Product'!D31/1000000 -> 118400.95 | E18: ='Dot Product'!E31/1000000 -> 161038.14 | F18: ='Dot Product'!F31/1000000 -> 229409.96 | G18: ='Dot Product'!G31/1000000 -> 119266.14 | H18: ='Dot Product'!H31/1000000 -> 713693.99 | I18: ='Dot Product'!I31/1000000 -> 70435.705 | ... N18: ='Dot Product'!N31/1000000 -> 112643.91
A19: Nlk | B19: ='Dot Product'!B39/1000000 -> 46751505 | C19: ='Dot Product'!C39/1000000 -> 391046.01 | D19: ='Dot Product'!D39/1000000 -> 235102.36 | E19: ='Dot Product'!E39/1000000 -> 174271.97 | F19: ='Dot Product'!F39/1000000 -> 297592.8 | G19: ='Dot Product'!G39/1000000 -> 170100.98 | H19: ='Dot Product'!H39/1000000 -> 1044348.6 | I19: ='Dot Product'!I39/1000000 -> 146257.21 | ... N19: ='Dot Product'!N39/1000000 -> 151287.87
A20: Cdk15 | B20: ='Dot Product'!B14/1000000 -> 26488963 | C20: ='Dot Product'!C14/1000000 -> 372627.56 | D20: ='Dot Product'!D14/1000000 -> 84372.306 | E20: ='Dot Product'!E14/1000000 -> 150996.02 | F20: ='Dot Product'!F14/1000000 -> 170305.56 | G20: ='Dot Product'!G14/1000000 -> 87301.082 | H20: ='Dot Product'!H14/1000000 -> 522146.91 | I20: ='Dot Product'!I14/1000000 -> 51555.049 | ... N20: ='Dot Product'!N14/1000000 -> 82973.654
A21: Mapk15 | B21: ='Dot Product'!B40/1000000 -> 44452251 | C21: ='Dot Product'!C40/1000000 -> 371814.28 | D21: ='Dot Product'!D40/1000000 -> 223539.95 | E21: ='Dot Product'!E40/1000000 -> 165701.23 | F21: ='Dot Product'!F40/1000000 -> 282957.09 | G21: ='Dot Product'!G40/1000000 -> 161735.36 | H21: ='Dot Product'!H40/1000000 -> 992987.19 | I21: ='Dot Product'!I40/1000000 -> 139064.24 | ... N21: ='Dot Product'!N40/1000000 -> 143847.49
A22: Cdk17 | B22: ='Dot Product'!B4/1000000 -> 22094709 | C22: ='Dot Product'!C4/1000000 -> 361015.84 | D22: ='Dot Product'!D4/1000000 -> 77336.011 | E22: ='Dot Product'!E4/1000000 -> 145880 | F22: ='Dot Product'!F4/1000000 -> 140697.5 | G22: ='Dot Product'!G4/1000000 -> 73127.404 | H22: ='Dot Product'!H4/1000000 -> 440557.09 | I22: ='Dot Product'!I4/1000000 -> 49030.527 | ... N22: ='Dot Product'!N4/1000000 -> 68708.572
A23: Mapk10 | B23: ='Dot Product'!B33/1000000 -> 32582137 | C23: ='Dot Product'!C33/1000000 -> 359569.41 | D23: ='Dot Product'!D33/1000000 -> 109650.33 | E23: ='Dot Product'!E33/1000000 -> 147622.78 | F23: ='Dot Product'!F33/1000000 -> 210600.92 | G23: ='Dot Product'!G33/1000000 -> 109675.82 | H23: ='Dot Product'!H33/1000000 -> 656616.96 | I23: ='Dot Product'!I33/1000000 -> 65302.227 | ... N23: ='Dot Product'!N33/1000000 -> 103475.17
A24: Cdk16 | B24: ='Dot Product'!B5/1000000 -> 22921620 | C24: ='Dot Product'!C5/1000000 -> 339943.25 | D24: ='Dot Product'!D5/1000000 -> 66229.983 | E24: ='Dot Product'!E5/1000000 -> 137547.65 | F24: ='Dot Product'!F5/1000000 -> 147594.48 | G24: ='Dot Product'!G5/1000000 -> 74245.154 | H24: ='Dot Product'!H5/1000000 -> 441944.94 | I24: ='Dot Product'!I5/1000000 -> 40295.335 | ... N24: ='Dot Product'!N5/1000000 -> 71385.916
A25: Cdk14 | B25: ='Dot Product'!B9/1000000 -> 23899690 | C25: ='Dot Product'!C9/1000000 -> 334112.86 | D25: ='Dot Product'!D9/1000000 -> 68136.227 | E25: ='Dot Product'!E9/1000000 -> 136436.5 | F25: ='Dot Product'!F9/1000000 -> 154225.05 | G25: ='Dot Product'!G9/1000000 -> 77480.814 | H25: ='Dot Product'!H9/1000000 -> 460646.35 | I25: ='Dot Product'!I9/1000000 -> 41017.25 | ... N25: ='Dot Product'!N9/1000000 -> 74598.735
A26: Mak | B26: ='Dot Product'!B11/1000000 -> 20430380 | C26: ='Dot Product'!C11/1000000 -> 285612.6 | D26: ='Dot Product'!D11/1000000 -> 58245.484 | E26: ='Dot Product'!E11/1000000 -> 116631.2 | F26: ='Dot Product'!F11/1000000 -> 131837.54 | G26: ='Dot Product'!G11/1000000 -> 66233.598 | H26: ='Dot Product'!H11/1000000 -> 393778.32 | I26: ='Dot Product'!I11/1000000 -> 35063.133 | ... N26: ='Dot Product'!N11/1000000 -> 63769.886
A27: Srpk2 | B27: ='Dot Product'!B25/1000000 -> 2003584.7 | C27: ='Dot Product'!C25/1000000 -> 271059.79 | D27: ='Dot Product'!D25/1000000 -> 23909.334 | E27: ='Dot Product'!E25/1000000 -> 132528.6 | F27: ='Dot Product'!F25/1000000 -> 5875.6673 | G27: ='Dot Product'!G25/1000000 -> 3393.6895 | H27: ='Dot Product'!H25/1000000 -> 31489.467 | I27: ='Dot Product'!I25/1000000 -> 24556.077 | ... N27: ='Dot Product'!N25/1000000 -> 1479.6424
A28: Ick | B28: ='Dot Product'!B7/1000000 -> 18095480 | C28: ='Dot Product'!C7/1000000 -> 252971.15 | D28: ='Dot Product'!D7/1000000 -> 51588.857 | E28: ='Dot Product'!E7/1000000 -> 103301.92 | F28: ='Dot Product'!F7/1000000 -> 116770.4 | G28: ='Dot Product'!G7/1000000 -> 58664.045 | H28: ='Dot Product'!H7/1000000 -> 348775.09 | I28: ='Dot Product'!I7/1000000 -> 31055.917 | ... N28: ='Dot Product'!N7/1000000 -> 56481.899
A29: Srpk3 | B29: ='Dot Product'!B23/1000000 -> 1396119.2 | C29: ='Dot Product'!C23/1000000 -> 200137.31 | D29: ='Dot Product'!D23/1000000 -> 7508.671 | E29: ='Dot Product'!E23/1000000 -> 99541.86 | F29: ='Dot Product'!F23/1000000 -> 4413.1996 | G29: ='Dot Product'!G23/1000000 -> 545.11166 | H29: ='Dot Product'!H23/1000000 -> 8184.3164 | I29: ='Dot Product'!I23/1000000 -> 11304.676 | ... N29: ='Dot Product'!N23/1000000 -> 420.15365
A30: Cdk12 | B30: ='Dot Product'!B8/1000000 -> 9047739.9 | C30: ='Dot Product'!C8/1000000 -> 126485.58 | D30: ='Dot Product'!D8/1000000 -> 25794.429 | E30: ='Dot Product'!E8/1000000 -> 51650.959 | F30: ='Dot Product'!F8/1000000 -> 58385.198 | G30: ='Dot Product'!G8/1000000 -> 29332.022 | H30: ='Dot Product'!H8/1000000 -> 174387.54 | I30: ='Dot Product'!I8/1000000 -> 15527.959 | ... N30: ='Dot Product'!N8/1000000 -> 28240.95
A31: Cdk13 | B31: ='Dot Product'!B12/1000000 -> 8104931.1 | C31: ='Dot Product'!C12/1000000 -> 112075.85 | D31: ='Dot Product'!D12/1000000 -> 23036.94 | E31: ='Dot Product'!E12/1000000 -> 45775.301 | F31: ='Dot Product'!F12/1000000 -> 52327.214 | G31: ='Dot Product'!G12/1000000 -> 26283.899 | H31: ='Dot Product'!H12/1000000 -> 156222.87 | I31: ='Dot Product'!I12/1000000 -> 13831.905 | ... N31: ='Dot Product'!N12/1000000 -> 25313.483
A32: Cdk11b | B32: ='Dot Product'!B27/1000000 -> 1017100.7 | C32: ='Dot Product'!C27/1000000 -> 101985.2 | D32: ='Dot Product'!D27/1000000 -> 1944.2785 | E32: ='Dot Product'!E27/1000000 -> 33672.789 | F32: ='Dot Product'!F27/1000000 -> 5650.4061 | G32: ='Dot Product'!G27/1000000 -> 2454.0917 | H32: ='Dot Product'!H27/1000000 -> 15125.607 | I32: ='Dot Product'!I27/1000000 -> 2369.989 | ... N32: ='Dot Product'!N27/1000000 -> 2502.8317
A33: Mapk4 | B33: ='Dot Product'!B17/1000000 -> 938846.88 | C33: ='Dot Product'!C17/1000000 -> 63619.119 | D33: ='Dot Product'!D17/1000000 -> 4174.1835 | E33: ='Dot Product'!E17/1000000 -> 29598.057 | F33: ='Dot Product'!F17/1000000 -> 4826.6882 | G33: ='Dot Product'!G17/1000000 -> 2131.9942 | H33: ='Dot Product'!H17/1000000 -> 14163.795 | I33: ='Dot Product'!I17/1000000 -> 4306.7219 | ... N33: ='Dot Product'!N17/1000000 -> 1950.6121
A34: Mapk6 | B34: ='Dot Product'!B16/1000000 -> 744207.63 | C34: ='Dot Product'!C16/1000000 -> 50429.791 | D34: ='Dot Product'!D16/1000000 -> 3308.8039 | E34: ='Dot Product'!E16/1000000 -> 23461.878 | F34: ='Dot Product'!F16/1000000 -> 3826.0319 | G34: ='Dot Product'!G16/1000000 -> 1689.9947 | H34: ='Dot Product'!H16/1000000 -> 11227.394 | I34: ='Dot Product'!I16/1000000 -> 3413.8652 | ... N34: ='Dot Product'!N16/1000000 -> 1546.2158
A35: Gsk3a | B35: ='Dot Product'!B42/1000000 -> 3062451.7 | C35: ='Dot Product'!C42/1000000 -> 36575.095 | D35: ='Dot Product'!D42/1000000 -> 6766.4753 | E35: ='Dot Product'!E42/1000000 -> 11203.437 | F35: ='Dot Product'!F42/1000000 -> 20269.256 | G35: ='Dot Product'!G42/1000000 -> 10064.366 | H35: ='Dot Product'!H42/1000000 -> 58838.178 | I35: ='Dot Product'!I42/1000000 -> 3319.2524 | ... N35: ='Dot Product'!N42/1000000 -> 9892.0412
A36: Cdk7 | B36: ='Dot Product'!B26/1000000 -> 2322020.5 | C36: ='Dot Product'!C26/1000000 -> 17091.307 | D36: ='Dot Product'!D26/1000000 -> 19710.477 | E36: ='Dot Product'!E26/1000000 -> 6243.1997 | F36: ='Dot Product'!F26/1000000 -> 14314.567 | G36: ='Dot Product'!G26/1000000 -> 9850.0348 | H36: ='Dot Product'!H26/1000000 -> 62941.57 | I36: ='Dot Product'!I26/1000000 -> 12639.091 | ... N36: ='Dot Product'!N26/1000000 -> 7875.918
A37: Cdkl1 | B37: ='Dot Product'!B20/1000000 -> 279628.88 | C37: ='Dot Product'!C20/1000000 -> 16361.248 | D37: ='Dot Product'!D20/1000000 -> 20785.821 | E37: ='Dot Product'!E20/1000000 -> 4778.679 | F37: ='Dot Product'!F20/1000000 -> 211.86813 | G37: ='Dot Product'!G20/1000000 -> 3943.0782 | H37: ='Dot Product'!H20/1000000 -> 30626.326 | I37: ='Dot Product'!I20/1000000 -> 14497.658 | ... N37: ='Dot Product'!N20/1000000 -> 1371.243
A38: Prpf4b | B38: ='Dot Product'!B24/1000000 -> 32842.159 | C38: ='Dot Product'!C24/1000000 -> 4639.8909 | D38: ='Dot Product'!D24/1000000 -> 231.95961 | E38: ='Dot Product'!E24/1000000 -> 2298.0852 | F38: ='Dot Product'!F24/1000000 -> 101.88796 | G38: ='Dot Product'!G24/1000000 -> 23.825243 | H38: ='Dot Product'!H24/1000000 -> 275.70775 | I38: ='Dot Product'!I24/1000000 -> 301.02957 | ... N38: ='Dot Product'!N24/1000000 -> 13.578487
A39: Dyrk1b | B39: ='Dot Product'!B22/1000000 -> 15849.048 | C39: ='Dot Product'!C22/1000000 -> 2310.199 | D39: ='Dot Product'!D22/1000000 -> 54.119501 | E39: ='Dot Product'!E22/1000000 -> 1154.42 | F39: ='Dot Product'!F22/1000000 -> 51.185687 | G39: ='Dot Product'!G22/1000000 -> 0.003162703 | H39: ='Dot Product'!H22/1000000 -> 46.139888 | I39: ='Dot Product'!I22/1000000 -> 108.58365 | ... N39: ='Dot Product'!N22/1000000 -> 2.6959561
A40: Dyrk1a | B40: ='Dot Product'!B21/1000000 -> 12119.517 | C40: ='Dot Product'!C21/1000000 -> 1766.5984 | D40: ='Dot Product'!D21/1000000 -> 41.383875 | E40: ='Dot Product'!E21/1000000 -> 882.78492 | F40: ='Dot Product'!F21/1000000 -> 39.140527 | G40: ='Dot Product'!G21/1000000 -> 0.0015899329 | H40: ='Dot Product'!H21/1000000 -> 35.277951 | I40: ='Dot Product'!I21/1000000 -> 83.03325 | ... N40: ='Dot Product'!N21/1000000 -> 2.0605582
...
